Workbook

Sheet 二供-功耗折算表
C1: Measured Results
A3: Sub-Module | B3: Net- | C3: Vavg (V) | D3: Iavg (mA) | E3: Pavg (mW)
A5: PMIC | B5: VIO18_PMU_6319 | C5: =L15 -> 0 | D5: =_xlfn.IFNA(HLOOKUP(B5&"_I",'二供-测试数据'!$A$3:$ZZ$32,4,FALSE),0) -> -1 | E5: =_xlfn.IFNA(HLOOKUP(B5&"_P",'二供-测试数据'!$A$3:$ZZ$32,4,FALSE),0) -> 0
A6: MT6720 | B6: VSYS_CHG | C6: =_xlfn.IFNA(HLOOKUP(B6&"_V",'二供-测试数据'!$A$3:$ZZ$32,4,FALSE)/1000,0) -> 4.00375 | D6: =_xlfn.IFNA(HLOOKUP(B6&"_I",'二供-测试数据'!$A$3:$ZZ$32,4,FALSE),0) -> 54.5 | E6: =_xlfn.IFNA(HLOOKUP(B6&"_P",'二供-测试数据'!$A$3:$ZZ$32,4,FALSE),0) -> 0
A7: BOB | B7: VBB1_BOB | C7: =_xlfn.IFNA(HLOOKUP(B7&"_V",'二供-测试数据'!$A$3:$ZZ$32,4,FALSE)/1000,0) -> 3.5125 | D7: =_xlfn.IFNA(HLOOKUP(B7&"_I",'二供-测试数据'!$A$3:$ZZ$32,4,FALSE),0) -> 3.5 | E7: =_xlfn.IFNA(HLOOKUP(B7&"_P",'二供-测试数据'!$A$3:$ZZ$32,4,FALSE),0) -> 0
A8: SPK | B8: VSYS_SPK | C8: =_xlfn.IFNA(HLOOKUP(B8&"_V",'二供-测试数据'!$A$3:$ZZ$32,4,FALSE)/1000,0) -> 3.9975 | D8: =_xlfn.IFNA(HLOOKUP(B8&"_I",'二供-测试数据'!$A$3:$ZZ$32,4,FALSE),0) -> -1 | E8: =_xlfn.IFNA(HLOOKUP(B8&"_P",'二供-测试数据'!$A$3:$ZZ$32,4,FALSE),0) -> 0
A9: DDR | B9: EMI_VDDQ_DDR | C9: =_xlfn.IFNA(HLOOKUP(B9&"_V",'二供-测试数据'!$A$3:$ZZ$32,4,FALSE)/1000,0) -> 0.50125 | D9: =_xlfn.IFNA(HLOOKUP(B9&"_I",'二供-测试数据'!$A$3:$ZZ$32,4,FALSE),0) -> 2.5 | E9: =_xlfn.IFNA(HLOOKUP(B9&"_P",'二供-测试数据'!$A$3:$ZZ$32,4,FALSE),0) -> 0
A10: DDR | B10: EMI_VDD2L_DDR | C10: =_xlfn.IFNA(HLOOKUP(B10&"_V",'二供-测试数据'!$A$3:$ZZ$32,4,FALSE)/1000,0) -> 0.91 | D10: =_xlfn.IFNA(HLOOKUP(B10&"_I",'二供-测试数据'!$A$3:$ZZ$32,4,FALSE),0) -> 3.5 | E10: =_xlfn.IFNA(HLOOKUP(B10&"_P",'二供-测试数据'!$A$3:$ZZ$32,4,FALSE),0) -> 0
A11: DDR | B11: EMI_VDD1_DDR | C11: =_xlfn.IFNA(HLOOKUP(B11&"_V",'二供-测试数据'!$A$3:$ZZ$32,4,FALSE)/1000,0) -> 1.805 | D11: =_xlfn.IFNA(HLOOKUP(B11&"_I",'二供-测试数据'!$A$3:$ZZ$32,4,FALSE),0) -> 1.475 | E11: =_xlfn.IFNA(HLOOKUP(B11&"_P",'二供-测试数据'!$A$3:$ZZ$32,4,FALSE),0) -> 0
A12: UFS | B12: UFS_VCC_2V5_UFS | C12: =_xlfn.IFNA(HLOOKUP(B12&"_V",'二供-测试数据'!$A$3:$ZZ$32,4,FALSE)/1000,0) -> 0 | D12: =_xlfn.IFNA(HLOOKUP(B12&"_I",'二供-测试数据'!$A$3:$ZZ$32,4,FALSE),0) -> 0.125 | E12: =_xlfn.IFNA(HLOOKUP(B12&"_P",'二供-测试数据'!$A$3:$ZZ$32,4,FALSE),0) -> 0
A13: UFS | B13: VUFS12_PMU | C13: =_xlfn.IFNA(HLOOKUP(B13&"_V",'二供-测试数据'!$A$3:$ZZ$32,4,FALSE)/1000,0) -> 1.19875 | D13: =_xlfn.IFNA(HLOOKUP(B13&"_I",'二供-测试数据'!$A$3:$ZZ$32,4,FALSE),0) -> 0.375 | E13: =_xlfn.IFNA(HLOOKUP(B13&"_P",'二供-测试数据'!$A$3:$ZZ$32,4,FALSE),0) -> 0
A14: MT6685 | B14: VIO18_PMU_6685 | C14: =_xlfn.IFNA(HLOOKUP(B14&"_V",'二供-测试数据'!$A$3:$ZZ$32,4,FALSE)/1000,0) -> 1.81875 | D14: =_xlfn.IFNA(HLOOKUP(B14&"_I",'二供-测试数据'!$A$3:$ZZ$32,4,FALSE),0) -> 3.5 | E14: =_xlfn.IFNA(HLOOKUP(B14&"_P",'二供-测试数据'!$A$3:$ZZ$32,4,FALSE),0) -> 0
A15: MT6685 | B15: VSYS_6685 | C15: =_xlfn.IFNA(HLOOKUP(B15&"_V",'二供-测试数据'!$A$3:$ZZ$32,4,FALSE)/1000,0) -> 4.00375 | D15: =_xlfn.IFNA(HLOOKUP(B15&"_I",'二供-测试数据'!$A$3:$ZZ$32,4,FALSE),0) -> 2.5 | E15: =_xlfn.IFNA(HLOOKUP(B15&"_P",'二供-测试数据'!$A$3:$ZZ$32,4,FALSE),0) -> 0
A16: SPK | B16: VIO18_PMU_SPK | C16: =_xlfn.IFNA(HLOOKUP(B16&"_V",'二供-测试数据'!$A$3:$ZZ$32,4,FALSE)/1000,0) -> 0 | D16: =_xlfn.IFNA(HLOOKUP(B16&"_I",'二供-测试数据'!$A$3:$ZZ$32,4,FALSE),0) -> 0 | E16: =_xlfn.IFNA(HLOOKUP(B16&"_P",'二供-测试数据'!$A$3:$ZZ$32,4,FALSE),0) -> 0
A17: REV | B17: VIO18_PMU_REV | C17: =_xlfn.IFNA(HLOOKUP(B17&"_V",'二供-测试数据'!$A$3:$ZZ$32,4,FALSE)/1000,0) -> 0 | D17: =_xlfn.IFNA(HLOOKUP(B17&"_I",'二供-测试数据'!$A$3:$ZZ$32,4,FALSE),0) -> 0 | E17: =_xlfn.IFNA(HLOOKUP(B17&"_P",'二供-测试数据'!$A$3:$ZZ$32,4,FALSE),0) -> 0
... A128: WCN | B128: AVDD33_WBT_WCN | C128: =_xlfn.IFNA(HLOOKUP(B128&"_V",'二供-测试数据'!$A$3:$ZZ$32,4,FALSE)/1000,0) -> 0 | D128: =_xlfn.IFNA(HLOOKUP(B128&"_I",'二供-测试数据'!$A$3:$ZZ$32,4,FALSE),0) -> 0 | E128: =_xlfn.IFNA(HLOOKUP(B128&"_P",'二供-测试数据'!$A$3:$ZZ$32,4,FALSE),0) -> 0

Sheet 二供-测试数据
A1: 07/28/26 15:37:11 | B1: Start Time: | C1: 1.7852242e+09 | D1: Duration: | E1: 72.4845 | F1: Time Precision: | G1: 4 | H1: Time Adjustment: | I1: 0 | J1: Target Size: | K1: 100
A3: Time Offset | B3: AVDD_I | C3: AVDD_P | D3: AVDD_V | E3: CAM_AFVDD2_2V8_I | F3: CAM_AFVDD2_2V8_P | G3: CAM_AFVDD2_2V8_V | H3: CH15_SPM_I | I3: CH15_SPM_P | J3: CH15_SPM_V | K3: CH23_SPM_I | L3: CH23_SPM_P | M3: CH23_SPM_V | N3: ELVDD_I | O3: ELVDD_P | P3: ELVDD_V | Q3: EMI_VDD1_DDR_I | R3: EMI_VDD1_DDR_P | S3: EMI_VDD1_DDR_V | T3: EMI_VDD2H_DDR_I | U3: EMI_VDD2H_DDR_P | V3: EMI_VDD2H_DDR_V | W3: EMI_VDD2L_DDR_I | X3: EMI_VDD2L_DDR_P | Y3: EMI_VDD2L_DDR_V | Z3: EMI_VDDQ_DDR_I | AA3: EMI_VDDQ_DDR_P | AB3: EMI_VDDQ_DDR_V | AC3: FCAM_AVDD_2P8_I | AD3: FCAM_AVDD_2P8_P | AE3: FCAM_AVDD_2P8_V | AF3: FCAM_DVDD_1P05_I | AG3: FCAM_DVDD_1P05_P | AH3: FCAM_DVDD_1P05_V | AI3: FCAM_VCAMIO_I | AJ3: FCAM_VCAMIO_P | AK3: FCAM_VCAMIO_V | AL3: MCAM_AVDD_2P8_I | AM3: MCAM_AVDD_2P8_P | AN3: MCAM_AVDD_2P8_V | AO3: MCAM_DVDD_1V1_I | AP3: MCAM_DVDD_1V1_P | AQ3: MCAM_DVDD_1V1_V | AR3: OLED_DVDD_I | AS3: OLED_DVDD_P | AT3: OLED_DVDD_V | AU3: OLED_VCI_I | AV3: OLED_VCI_P | AW3: OLED_VCI_V | AX3: OLED_VDDI_I | AY3: OLED_VDDI_P | AZ3: OLED_VDDI_V | BA3: SAR_VDD_1P8_I | BB3: SAR_VDD_1P8_P | BC3: SAR_VDD_1P8_V | BD3: System Messages | BF3: TSP_IO_CON_I | BG3: TSP_IO_CON_P | BH3: TSP_IO_CON_V | BI3: UFS_VCC_2V5_UFS_I | BJ3: UFS_VCC_2V5_UFS_P | BK3: UFS_VCC_2V5_UFS_V | BL3: VBB1_BOB_I | BM3: VBB1_BOB_P | BN3: VBB1_BOB_V | BO3: VCAMIO_I | BP3: VCAMIO_P | BQ3: VCAMIO_V | BR3: VCAMIO_WIDE_I | BS3: VCAMIO_WIDE_P | BT3: VCAMIO_WIDE_V | BU3: VIO18_PMU_6319_I | BV3: VIO18_PMU_6319_P | BW3: VIO18_PMU_6319_V | BX3: VIO18_PMU_6685_I | BY3: VIO18_PMU_6685_P | BZ3: VIO18_PMU_6685_V | CA3: VIO18_PMU_A_G_I | CB3: VIO18_PMU_A_G_P | CC3: VIO18_PMU_A_G_V | CD3: VIO18_PMU_FLICKER_I | CE3: VIO18_PMU_FLICKER_P | CF3: VIO18_PMU_FLICKER_V | CG3: VIO18_PMU_HAC_I | CH3: VIO18_PMU_HAC_P | CI3: VIO18_PMU_HAC_V | CJ3: VIO18_PMU_M_I | CK3: VIO18_PMU_M_P | CL3: VIO18_PMU_M_V | CM3: VIO18_PMU_PL_I | CN3: VIO18_PMU_PL_P | CO3: VIO18_PMU_PL_V | CP3: VIO18_PMU_REV_I | CQ3: VIO18_PMU_REV_P | CR3: VIO18_PMU_REV_V | CS3: VIO18_PMU_SPK_I | CT3: VIO18_PMU_SPK_P | CU3: VIO18_PMU_SPK_V | CV3: VLEDA_PL_I | CW3: VLEDA_PL_P | CX3: VLEDA_PL_V | CY3: VSYS_6685_I | CZ3: VSYS_6685_P | DA3: VSYS_6685_V | DB3: VSYS_AVDD_I | DC3: VSYS_AVDD_P | DD3: VSYS_AVDD_V | DE3: VSYS_CHG_I | DF3: VSYS_CHG_P | DG3: VSYS_CHG_V | DH3: VSYS_DVE_I | DI3: VSYS_DVE_P | DJ3: VSYS_DVE_V | DK3: VSYS_ELVDD_I | DL3: VSYS_ELVDD_P | DM3: VSYS_ELVDD_V | DN3: VSYS_FLASH_I | DO3: VSYS_FLASH_P | DP3: VSYS_FLASH_V | DQ3: VSYS_HAC_I | DR3: VSYS_HAC_P | DS3: VSYS_HAC_V | DT3: VSYS_PVIN_I | DU3: VSYS_PVIN_P | DV3: VSYS_PVIN_V | DW3: VSYS_REV_I | DX3: VSYS_REV_P | DY3: VSYS_REV_V | DZ3: VSYS_SPK_I | EA3: VSYS_SPK_P | EB3: VSYS_SPK_V | EC3: VSYS_VIB_I | ED3: VSYS_VIB_P | EE3: VSYS_VIB_V | EF3: VTP_PMU_I | EG3: VTP_PMU_P | EH3: VTP_PMU_V | EI3: VUFS12_PMU_I | EJ3: VUFS12_PMU_P | EK3: VUFS12_PMU_V | EL3: WCAM_AVDD_2P8_I | EM3: WCAM_AVDD_2P8_P | EN3: WCAM_AVDD_2P8_V | EO3: WIDE_DVDD_1P2_I | EP3: WIDE_DVDD_1P2_P | EQ3: WIDE_DVDD_1P2_V
B5: EPM332.0 | C5: EPM332.0P | D5: EPM333.0 | E5: EPM304.0 | F5: EPM304.0P | G5: EPM305.0 | H5: EPM358.0 | I5: EPM358.0P | J5: EPM359.0 | K5: EPM362.0 | L5: EPM362.0P | M5: EPM363.0 | N5: EPM268.0 | O5: EPM268.0P | P5: EPM269.0 | Q5: EPM322.0 | R5: EPM322.0P | S5: EPM323.0 | T5: EPM300.0 | U5: EPM300.0P | V5: EPM301.0 | W5: EPM290.0 | X5: EPM290.0P | Y5: EPM291.0 | Z5: EPM258.0 | AA5: EPM258.0P | AB5: EPM259.0 | AC5: EPM306.0 | AD5: EPM306.0P | AE5: EPM307.0 | AF5: EPM370.0 | AG5: EPM370.0P | AH5: EPM371.0 | AI5: EPM338.0 | AJ5: EPM338.0P | AK5: EPM339.0 | AL5: EPM334.0 | AM5: EPM334.0P | AN5: EPM335.0 | AO5: EPM272.0 | AP5: EPM272.0P | AQ5: EPM273.0 | AR5: EPM302.0 | AS5: EPM302.0P | AT5: EPM303.0 | AU5: EPM364.0 | AV5: EPM364.0P | AW5: EPM365.0 | AX5: EPM270.0 | AY5: EPM270.0P | AZ5: EPM271.0 | BA5: EPM372.0 | BB5: EPM372.0P | BC5: EPM373.0 | BD5: serverMessages | BF5: EPM264.0 | BG5: EPM264.0P | BH5: EPM265.0 | BI5: EPM354.0 | BJ5: EPM354.0P | BK5: EPM355.0 | BL5: EPM320.0 | BM5: EPM320.0P | BN5: EPM321.0 | BO5: EPM366.0 | BP5: EPM366.0P | BQ5: EPM367.0 | BR5: EPM368.0 | BS5: EPM368.0P | BT5: EPM369.0 | BU5: EPM256.0 | BV5: EPM256.0P | BW5: EPM257.0 | BX5: EPM292.0 | BY5: EPM292.0P | BZ5: EPM293.0 | CA5: EPM278.0 | CB5: EPM278.0P | CC5: EPM279.0 | CD5: EPM374.0 | CE5: EPM374.0P | CF5: EPM375.0 | CG5: EPM326.0 | CH5: EPM326.0P | CI5: EPM327.0 | CJ5: EPM340.0 | CK5: EPM340.0P | CL5: EPM341.0 | CM5: EPM310.0 | CN5: EPM310.0P | CO5: EPM311.0 | CP5: EPM262.0 | CQ5: EPM262.0P | CR5: EPM263.0 | CS5: EPM356.0 | CT5: EPM356.0P | CU5: EPM357.0 | CV5: EPM342.0 | CW5: EPM342.0P | CX5: EPM343.0 | CY5: EPM324.0 | CZ5: EPM324.0P | DA5: EPM325.0 | DB5: EPM298.0 | DC5: EPM298.0P | DD5: EPM299.0 | DE5: EPM288.0 | DF5: EPM288.0P | DG5: EPM289.0 | DH5: EPM330.0 | DI5: EPM330.0P | DJ5: EPM331.0 | DK5: EPM360.0 | DL5: EPM360.0P | DM5: EPM361.0 | DN5: EPM276.0 | DO5: EPM276.0P | DP5: EPM277.0 | DQ5: EPM296.0 | DR5: EPM296.0P | DS5: EPM297.0 | DT5: EPM266.0 | DU5: EPM266.0P | DV5: EPM267.0 | DW5: EPM294.0 | DX5: EPM294.0P | DY5: EPM295.0 | DZ5: EPM352.0 | EA5: EPM352.0P | EB5: EPM353.0 | EC5: EPM308.0 | ED5: EPM308.0P | EE5: EPM309.0 | EF5: EPM328.0 | EG5: EPM328.0P | EH5: EPM329.0 | EI5: EPM260.0 | EJ5: EPM260.0P | EK5: EPM261.0 | EL5: EPM274.0 | EM5: EPM274.0P | EN5: EPM275.0 | EO5: EPM336.0 | EP5: EPM336.0P | EQ5: EPM337.0
A6: 1.2532 | B6: 3.9 | D6: 7398.75 | E6: 0.05 | G6: 0 | H6: -0.125 | J6: 2.5 | K6: -0.05 | M6: 0 | N6: 8.05 | P6: 4605 | Q6: 1.475 | S6: 1805 | T6: 0.55 | V6: 1061.25 | W6: 3.5 | Y6: 910 | Z6: 2.5 | AB6: 501.25 | AC6: 0.125 | AE6: 0 | AF6: 0.125 | AH6: 0 | AI6: 0 | AK6: 1822.5 | AL6: 0 | AN6: 0 | AO6: 0 | AQ6: 0 | AR6: 13.675 | AT6: 1298.75 | AU6: 0.175 | AW6: 2997.5 | AX6: 3.35 | AZ6: 1798.75 | BA6: 0 | BC6: 1815 | BF6: 0.175 | BH6: 1810 | BI6: 0.125 | BK6: 0 | BL6: 3.5 | BN6: 3512.5 | BO6: 0 | BQ6: 1832.5 | BR6: -0.05 | BT6: 1822.5 | BU6: -1 | BW6: 1818.75 | BX6: 3.5 | BZ6: 1818.75 | CA6: 0.25 | CC6: 1813.75 | CD6: 537.7 | CF6: 1762.5 | CG6: -1 | CI6: 1822.5 | CJ6: 0.05 | CL6: 1821.25 | CM6: 0.25 | CO6: 1816.25 | CP6: 0.125 | CR6: 1816.25 | CS6: -1 | CU6: 1817.5 | CV6: -0.05 | CX6: 3311.25 | CY6: 2.5 | DA6: 4003.75 | DB6: 7.6 | DD6: 4002.5 | DE6: 54.5 | DG6: 4003.75 | DH6: 1 | DJ6: 3997.5 | DK6: 11 | DM6: 4000 | DN6: -0.175 | DP6: 3997.5 | DQ6: -1 | DS6: 4003.75 | DT6: 2.85 | DV6: 3998.75 | DW6: 1 | DY6: 3998.75 | DZ6: -1 | EB6: 3997.5 | EC6: 0 | EE6: 4002.5 | EF6: 0.125 | EH6: 3315 | EI6: 0.375 | EK6: 1198.75 | EL6: 0.05 | EN6: 0 | EO6: 0 | EQ6: 2.5
A7: 1.3492 | B7: 16.005 | C7: 118.337 | D7: 7393.75 | E7: -0.02 | F7: 0 | G7: 1.375 | H7: -0.0275 | I7: 0 | J7: 1.625 | K7: 0.0125 | L7: 0 | M7: 0.625 | N7: 8.025 | O7: 36.922 | P7: 4600.875 | Q7: 3.305 | R7: 5.9597 | S7: 1803.25 | T7: 10.965 | U7: 11.616 | V7: 1059.375 | W7: 2.85 | X7: 2.6273 | Y7: 921.875 | Z7: 1.2 | AA7: 0.6045 | AB7: 503.75 | AC7: -0.0025 | AD7: 0 | AE7: 0.5 | AF7: -0.0175 | AG7: 0 | AH7: 1 | AI7: 0.0125 | AJ7: 0.0228 | AK7: 1821.625 | AL7: 0.02 | AM7: 0 | AN7: 0 | AO7: 0.15 | AP7: 0.0003 | AQ7: 1.75 | AR7: 53.6525 | AS7: 69.1715 | AT7: 1289.25 | AU7: 0.09 | AV7: 0.269 | AW7: 2989.375 | AX7: 7.9325 | AY7: 14.2914 | AZ7: 1801.625 | BA7: 0 | BB7: 0 | BC7: 1818.25 | BF7: 1.4575 | BG7: 2.6328 | BH7: 1806.375 | BI7: 0.0025 | BJ7: 0 | BK7: 2.375 | BL7: 4.1 | BM7: 14.4028 | BN7: 3512.875 | BO7: 0.0825 | BP7: 0.1503 | BQ7: 1822 | BR7: -0.0025 | BS7: -0.0046 | BT7: 1820.25 | BU7: 0.1 | BV7: 0.1819 | BW7: 1818.75 | BX7: 2.15 | BY7: 3.9157 | BZ7: 1821.25 | CA7: 0.1775 | CB7: 0.3233 | CC7: 1821.625 | CD7: 538.415 | CE7: 949.6295 | CF7: 1763.75 | CG7: 0.1 | CH7: 0.1824 | CI7: 1823.625 | CJ7: 0.0275 | CK7: 0.05 | CL7: 1817.875 | CM7: 0.1925 | CN7: 0.3502 | CO7: 1819 | CP7: 0.0075 | CQ7: 0.0136 | CR7: 1818.875 | CS7: -0.2 | CT7: -0.3639 | CU7: 1819.625 | CV7: 0.055 | CW7: 0.181 | CX7: 3291.25 | CY7: 0.45 | CZ7: 1.7948 | DA7: 3988.5 | DB7: 29.875 | DC7: 119.078 | DD7: 3985.875 | DE7: 113.5 | DF7: 453.2764 | DG7: 3993.625 | DH7: 0.94 | DI7: 3.7492 | DJ7: 3988.5 | DK7: 10.725 | DL7: 42.778 | DM7: 3988.625 | DN7: 0.0475 | DO7: 0.1896 | DP7: 3990.75 | DQ7: -0.5 | DR7: -1.9946 | DS7: 3989.25 | DT7: 2.98 | DU7: 11.885 | DV7: 3988.25 | DW7: 0.3 | DX7: 1.1975 | DY7: 3991.625 | DZ7: 1.25 | EA7: 4.9873 | EB7: 3989.875 | EC7: 0.0825 | ED7: 0.3293 | EE7: 3991.5 | EF7: 3.2925 | EG7: 10.9031 | EH7: 3311.5 | EI7: 0.3725 | EJ7: 0.4465 | EK7: 1198.75 | EL7: -0.015 | EM7: 0 | EN7: 0.75 | EO7: -0.0175 | EP7: 0 | EQ7: 0.25
A8: 1.4452 | B8: 15.325 | C8: 113.3399 | D8: 7395.75 | E8: 0.0175 | F8: 0 | G8: 1 | H8: -0.0275 | I8: 0 | J8: 1.375 | K8: -0.0275 | L8: 0 | M8: 1 | N8: 8 | O8: 36.831 | P8: 4603.875 | Q8: 3.4375 | R8: 6.1939 | S8: 1801.875 | T8: 13.76 | U8: 14.5409 | V8: 1056.75 | W8: 4.6 | X8: 4.2263 | Y8: 918.75 | Z8: 1.25 | AA8: 0.6278 | AB8: 502.25 | AC8: 0.0125 | AD8: 0 | AE8: 0.875 | AF8: -0.0125 | AG8: 0 | AH8: 1 | AI8: 0.015 | AJ8: 0.0273 | AK8: 1821.125 | AL8: -0.02 | AM8: 0 | AN8: 1.25 | AO8: -0.15 | AP8: -0.0001 | AQ8: 1 | AR8: 53.94 | AS8: 69.6163 | AT8: 1290.625 | AU8: 0.1275 | AV8: 0.3814 | AW8: 2991.375 | AX8: 7.93 | AY8: 14.3057 | AZ8: 1804 | BA8: 0.005 | BB8: 0.0091 | BC8: 1816.375 | BF8: 0.845 | BG8: 1.526 | BH8: 1805.875 | BI8: -0.025 | BJ8: 0 | BK8: 0.75 | BL8: 6.65 | BM8: 23.334 | BN8: 3508.875 | BO8: 0.04 | BP8: 0.0728 | BQ8: 1820.375 | BR8: 0 | BS8: 0 | BT8: 1820.5 | BU8: -0.8 | BV8: -1.4567 | BW8: 1820.875 | BX8: 2.55 | BY8: 4.64 | BZ8: 1819.625 | CA8: 0.175 | CB8: 0.3186 | CC8: 1820.5 | CD8: 538.255 | CE8: 948.8763 | CF8: 1762.875 | CG8: -0.1 | CH8: -0.1821 | CI8: 1821.375 | CJ8: 0.005 | CK8: 0.0091 | CL8: 1818.5 | CM8: 0.18 | CN8: 0.3275 | CO8: 1819.375 | CP8: -0.0025 | CQ8: -0.0045 | CR8: 1820 | CS8: 0 | CT8: 0 | CU8: 1821.5 | CV8: 0 | CW8: 0 | CX8: 3292.375 | CY8: 1.1 | CZ8: 4.3887 | DA8: 3989.75 | DB8: 30.3525 | DC8: 120.9964 | DD8: 3986.375 | DE8: 117.9 | DF8: 470.48 | DG8: 3990.5 | DH8: 0.925 | DI8: 3.6887 | DJ8: 3987.75 | DK8: 10.81 | DL8: 43.1278 | DM8: 3989.625 | DN8: 0.02 | DO8: 0.0798 | DP8: 3989.375 | DQ8: -0.3 | DR8: -1.197 | DS8: 3990 | DT8: 2.7375 | DU8: 10.9096 | DV8: 3985.25 | DW8: 0.95 | DX8: 3.7909 | DY8: 3990.375 | DZ8: 1.2 | EA8: 4.7886 | EB8: 3990.5 | EC8: 0.07 | ED8: 0.2794 | EE8: 3990.875 | EF8: 0.2625 | EG8: 0.8693 | EH8: 3311.75 | EI8: 0.32 | EJ8: 0.3848 | EK8: 1202.625 | EL8: -0.0075 | EM8: 0 | EN8: 0.875 | EO8: -0.0175 | EP8: 0 | EQ8: 2.25
A9: 1.5412 | B9: 15.38 | C9: 113.7197 | D9: 7394 | E9: 0 | F9: 0 | G9: 1.375 | H9: -0.0225 | I9: -0.0001 | J9: 2.25 | K9: -0.0475 | L9: -0.0001 | M9: 2.125 | N9: 7.9425 | O9: 36.5891 | P9: 4606.75 | Q9: 3.175 | R9: 5.7273 | S9: 1803.875 | T9: 11.49 | U9: 12.1579 | V9: 1058.125 | W9: 3.2 | X9: 2.9436 | Y9: 919.875 | Z9: 1.35 | AA9: 0.6785 | AB9: 502.625 | AC9: -0.0275 | AD9: 0 | AE9: 1.75 | AF9: -0.01 | AG9: 0 | AH9: 1 | AI9: -0.015 | AJ9: -0.0273 | AK9: 1821.75 | AL9: 0.005 | AM9: 0 | AN9: 0.5 | AO9: -0.05 | AP9: -0.0001 | AQ9: 1 | AR9: 51.725 | AS9: 66.8222 | AT9: 1291.875 | AU9: 0.13 | AV9: 0.389 | AW9: 2992.5 | AX9: 7.8875 | AY9: 14.2143 | AZ9: 1802.125 | BA9: 0.0275 | BB9: 0.05 | BC9: 1817.875 | BF9: 1.96 | BG9: 3.5393 | BH9: 1805.75 | BI9: 0.0025 | BJ9: 0 | BK9: 2.625 | BL9: 6 | BM9: 21.0555 | BN9: 3509.25 | BO9: 0.0575 | BP9: 0.1048 | BQ9: 1821.875 | BR9: 0.025 | BS9: 0.0455 | BT9: 1821.5 | BU9: -0.05 | BV9: -0.0909 | BW9: 1818.75 | BX9: 1.7 | BY9: 3.0944 | BZ9: 1820.25 | CA9: 0.1725 | CB9: 0.314 | CC9: 1820 | CD9: 538.575 | CE9: 949.2384 | CF9: 1762.5 | CG9: -0.3 | CH9: -0.5463 | CI9: 1820.875 | CJ9: 0.0175 | CK9: 0.0319 | CL9: 1820.375 | CM9: 0.0875 | CN9: 0.1591 | CO9: 1818.375 | CP9: -0.0075 | CQ9: -0.0137 | CR9: 1821.625 | CS9: 0.8 | CT9: 1.455 | CU9: 1818.75 | CV9: 0.04 | CW9: 0.1316 | CX9: 3289 | CY9: 1.05 | CZ9: 4.1873 | DA9: 3987.875 | DB9: 31.5 | DC9: 125.6574 | DD9: 3989.125 | DE9: 112.15 | DF9: 447.6187 | DG9: 3991.25 | DH9: 0.98 | DI9: 3.9096 | DJ9: 3989.375 | DK9: 10.8225 | DL9: 43.1493 | DM9: 3987 | DN9: 0.1025 | DO9: 0.4092 | DP9: 3992.25 | DQ9: 0 | DR9: 0 | DS9: 3990 | DT9: 2.885 | DU9: 11.5061 | DV9: 3988.25 | DW9: 0.4 | DX9: 1.5964 | DY9: 3990.875 | DZ9: 1.2 | EA9: 4.788 | EB9: 3990 | EC9: 0.025 | ED9: 0.0998 | EE9: 3991.5 | EF9: 0.2675 | EG9: 0.8858 | EH9: 3311.25 | EI9: 0.3125 | EJ9: 0.3746 | EK9: 1198.625 | EL9: -0.01 | EM9: 0 | EN9: 1.375 | EO9: -0.0125 | EP9: 0 | EQ9: 1.375
A10: 1.6372 | B10: 13.18 | C10: 97.4677 | D10: 7395.125 | E10: 0.0125 | F10: 0 | G10: 2.5 | H10: -0.01 | I10: 0 | J10: 2 | K10: 0.02 | L10: 0 | M10: 1.375 | N10: 7.995 | O10: 36.8 | P10: 4602.875 | Q10: 2.92 | R10: 5.2626 | S10: 1802.25 | T10: 8.4475 | U10: 8.9353 | V10: 1057.75 | W10: 2.8 | X10: 2.5767 | Y10: 920.25 | Z10: 1.55 | AA10: 0.7818 | AB10: 504.375 | AC10: -0.025 | AD10: 0 | AE10: 1.25 | AF10: 0.01 | AG10: 0 | AH10: 1.5 | AI10: 0.0275 | AJ10: 0.05 | AK10: 1819.25 | AL10: -0.01 | AM10: 0 | AN10: 1.25 | AO10: 0.35 | AP10: 0.0004 | AQ10: 1.125 | AR10: 47.8925 | AS10: 61.913 | AT10: 1292.75 | AU10: 0.0775 | AV10: 0.2319 | AW10: 2992.625 | AX10: 7.0375 | AY10: 12.6675 | AZ10: 1800 | BA10: 0.01 | BB10: 0.0182 | BC10: 1818.25 | BF10: 1.4125 | BG10: 2.5506 | BH10: 1805.75 | BI10: -0.0125 | BJ10: 0 | BK10: 0.5 | BL10: 3.35 | BM10: 11.7602 | BN10: 3510.5 | BO10: 0.0425 | BP10: 0.0774 | BQ10: 1822 | BR10: 0.0475 | BS10: 0.0865 | BT10: 1821.5 | BU10: -0.2 | BV10: -0.364 | BW10: 1820.125 | BX10: 1.8 | BY10: 3.2778 | BZ10: 1821 | CA10: 0.195 | CB10: 0.3545 | CC10: 1817.875 | CD10: 538.5375 | CE10: 949.3743 | CF10: 1762.875 | CG10: 0.15 | CH10: 0.2732 | CI10: 1821.25 | CJ10: 0.0225 | CK10: 0.0409 | CL10: 1819.375 | CM10: 0.18 | CN10: 0.3272 | CO10: 1817.625 | CP10: 0.0475 | CQ10: 0.0866 | CR10: 1823.75 | CS10: 0.8 | CT10: 1.455 | CU10: 1818.75 | CV10: 0.06 | CW10: 0.1975 | CX10: 3291.625 | CY10: 1.15 | CZ10: 4.5907 | DA10: 3991.875 | DB10: 25.5575 | DC10: 101.9776 | DD10: 3990.125 | DE10: 103.45 | DF10: 413.1793 | DG10: 3994 | DH10: 0.9475 | DI10: 3.7811 | DJ10: 3990.625 | DK10: 10.8175 | DL10: 43.1767 | DM10: 3991.375 | DN10: -0.0325 | DO10: -0.1297 | DP10: 3990.75 | DQ10: -0.1 | DR10: -0.3991 | DS10: 3991 | DT10: 3.1475 | DU10: 12.5558 | DV10: 3989.125 | DW10: 0.1 | DX10: 0.399 | DY10: 3990.375 | DZ10: 0.6 | EA10: 2.3948 | EB10: 3991.25 | EC10: 0.0675 | ED10: 0.2695 | EE10: 3993 | EF10: 0.515 | EG10: 1.705 | EH10: 3310.625 | EI10: 0.3475 | EJ10: 0.417 | EK10: 1200 | EL10: 0.01 | EM10: 0 | EN10: 1.75 | EO10: -0.01 | EP10: 0 | EQ10: 1.125
A11: 1.7332 | B11: 15.4575 | D11: 7392.375 | E11: 0.0175 | G11: 1.375 | H11: 0.02 | J11: 0.75 | K11: -0.0475 | M11: 1.125 | N11: 7.9475 | P11: 4603.625 | Q11: 3.4 | S11: 1802 | T11: 11.89 | V11: 1056.5 | W11: 3.1 | Y11: 921.125 | Z11: 0.3 | AB11: 501.75 | AC11: 0.0125 | AE11: 1.75 | AF11: 0.03 | AH11: 0.25 | AI11: 0.0425 | AK11: 1820.375 | AL11: -0.0075 | AN11: 1.25 | AO11: -0.25 | AQ11: 2.25 | AR11: 53.4225 | AT11: 1292.25 | AU11: 0.12 | AW11: 2992.75 | AX11: 7.845 | AZ11: 1800.25 | BA11: 0.035 | BC11: 1817.375 | BF11: 1.885 | BH11: 1805.5 | BI11: 0.0125 | BK11: 0.75 | BL11: 8.2 | BN11: 3508.75 | BO11: 0.0275 | BQ11: 1821.125 | BR11: -0.01 | BT11: 1820 | BU11: 1.15 | BW11: 1818.125 | BX11: 1.6 | BZ11: 1819.375 | CA11: 0.1875 | CC11: 1820.375 | CD11: 538.595 | CF11: 1765.5 | CG11: -0.25 | CI11: 1817.25 | CJ11: -0.02 | CL11: 1818.25 | CM11: 0.11 | CO11: 1817.875 | CP11: 0.02 | CR11: 1817.25 | CS11: 0.55 | CU11: 1819.5 | CV11: 0.01 | CX11: 3292 | CY11: 0.85 | DA11: 3988.75 | DB11: 30.4575 | DD11: 3985.625 | DE11: 114 | DG11: 3991.625 | DH11: 0.9375 | DJ11: 3989.5 | DK11: 10.805 | DM11: 3988.5 | DN11: 0.0525 | DP11: 3990.625 | DQ11: -0.45 | DS11: 3989.5 | DT11: 2.715 | DV11: 3988 | DW11: 0.25 | DY11: 3991.5 | DZ11: 0.8 | EB11: 3989.5 | EC11: 0.045 | EE11: 3991.25 | EF11: 0.32 | EH11: 3312.625 | EI11: 0.4475 | EK11: 1201 | EL11: -0.03 | EN11: 1 | EO11: 0.0075 | EQ11: 0.5
A12: 1.8292 | B12: 15.24 | C12: 112.6808 | D12: 7393.75 | E12: 0.0075 | F12: 0 | G12: 1.625 | H12: -0.025 | I12: -0.0001 | J12: 2 | K12: 0.0375 | L12: 0.0001 | M12: 1.625 | N12: 8 | O12: 36.833 | P12: 4604.125 | Q12: 3.11 | R12: 5.6104 | S12: 1804 | T12: 9.5375 | U12: 10.0788 | V12: 1056.75 | W12: 3.6 | X12: 3.3098 | Y12: 919.375 | Z12: 1.4 | AA12: 0.7047 | AB12: 503.375 | AC12: 0 | AD12: 0 | AE12: 1.25 | AF12: 0.0175 | AG12: 0 | AH12: 1.625 | AI12: 0.0225 | AJ12: 0.041 | AK12: 1821.25 | AL12: -0.0125 | AM12: 0 | AN12: 0.875 | AO12: 0.95 | AP12: 0.0011 | AQ12: 1.125 | AR12: 56.0325 | AS12: 72.1629 | AT12: 1287.875 | AU12: 0.09 | AV12: 0.2693 | AW12: 2992.75 | AX12: 7.8225 | AY12: 14.0981 | AZ12: 1802.25 | BA12: 0.0425 | BB12: 0.0773 | BC12: 1817.75 | BF12: 0.36 | BG12: 0.6498 | BH12: 1804.875 | BI12: -0.0325 | BJ12: 0 | BK12: 1.375 | BL12: 11 | BM12: 38.6183 | BN12: 3510.75 | BO12: 0.0725 | BP12: 0.132 | BQ12: 1820.125 | BR12: 0.0075 | BS12: 0.0136 | BT12: 1819.75 | BU12: 0.2 | BV12: 0.3638 | BW12: 1818.75 | BX12: 1.95 | BY12: 3.5517 | BZ12: 1821.375 | CA12: 0.1625 | CB12: 0.296 | CC12: 1821.375 | CD12: 538.195 | CE12: 948.7705 | CF12: 1762.875 | CG12: 0.05 | CH12: 0.091 | CI12: 1820.375 | CJ12: -0.0275 | CK12: -0.05 | CL12: 1817.625 | CM12: 0.1725 | CN12: 0.3134 | CO12: 1817 | CP12: 0.035 | CQ12: 0.0637 | CR12: 1819.5 | CS12: 0.35 | CT12: 0.6367 | CU12: 1819.125 | CV12: 0.03 | CW12: 0.0989 | CX12: 3295.125 | CY12: 0.3 | CZ12: 1.1971 | DA12: 3990.25 | DB12: 30.2 | DC12: 120.4074 | DD12: 3987 | DE12: 111.85 | DF12: 446.3514 | DG12: 3990.625 | DH12: 0.9625 | DI12: 3.841 | DJ12: 3990.625 | DK12: 10.7 | DL12: 42.6984 | DM12: 3990.5 | DN12: 0.11 | DO12: 0.439 | DP12: 3990.75 | DQ12: -0.75 | DR12: -2.9934 | DS12: 3991.25 | DT12: 2.895 | DU12: 11.5416 | DV12: 3986.75 | DW12: 0.65 | DX12: 2.5942 | DY12: 3991 | DZ12: 1.55 | EA12: 6.1829 | EB12: 3989 | EC12: 0.065 | ED12: 0.2594 | EE12: 3991.5 | EF12: 0.25 | EG12: 0.8281 | EH12: 3312.5 | EI12: 0.3075 | EJ12: 0.3692 | EK12: 1200.625 | EL12: -0.0075 | EM12: 0 | EN12: 1.625 | EO12: -0.02 | EP12: 0 | EQ12: 1.625
A13: 1.9252 | B13: 15.375 | C13: 113.7077 | D13: 7395.625 | E13: 0 | F13: 0 | G13: 2.375 | H13: 0.01 | I13: 0 | J13: 0.625 | K13: -0.0225 | L13: 0 | M13: 1.125 | N13: 7.995 | O13: 36.806 | P13: 4603.625 | Q13: 3.3775 | R13: 6.0884 | S13: 1802.625 | T13: 11.7025 | U13: 12.3827 | V13: 1058.125 | W13: 1.7 | X13: 1.5661 | Y13: 921.25 | Z13: 1.35 | AA13: 0.677 | AB13: 501.5 | AC13: -0.01 | AD13: 0 | AE13: 1 | AF13: -0.0075 | AG13: 0 | AH13: 0 | AI13: 0.025 | AJ13: 0.0455 | AK13: 1821.625 | AL13: 0.005 | AM13: 0 | AN13: 1.125 | AO13: -0.1 | AP13: -0.0001 | AQ13: 1 | AR13: 53.8 | AS13: 69.4894 | AT13: 1291.625 | AU13: 0.0725 | AV13: 0.2169 | AW13: 2991.375 | AX13: 7.9375 | AY13: 14.3024 | AZ13: 1801.875 | BA13: 0.0225 | BB13: 0.0409 | BC13: 1819.125 | BF13: 1.895 | BG13: 3.4209 | BH13: 1805.25 | BI13: -0.005 | BJ13: -0.0013 | BK13: 256.875 | BL13: 4.25 | BM13: 14.9159 | BN13: 3509.625 | BO13: 0.08 | BP13: 0.1456 | BQ13: 1820.375 | BR13: 0.035 | BS13: 0.0636 | BT13: 1817.875 | BU13: -0.15 | BV13: -0.2728 | BW13: 1818.75 | BX13: 2.45 | BY13: 4.4581 | BZ13: 1819.625 | CA13: 0.2275 | CB13: 0.414 | CC13: 1819.875 | CD13: 538.54 | CE13: 948.5709 | CF13: 1761.375 | CG13: 0.4 | CH13: 0.7287 | CI13: 1821.625 | CJ13: 0.025 | CK13: 0.0455 | CL13: 1819.125 | CM13: 0.2325 | CN13: 0.4231 | CO13: 1819.625 | CP13: 0.01 | CQ13: 0.0182 | CR13: 1821.75 | CS13: 0.7 | CT13: 1.2735 | CU13: 1819.25 | CV13: 0.0275 | CW13: 0.0906 | CX13: 3293.75 | CY13: 0.35 | CZ13: 1.396 | DA13: 3988.5 | DB13: 30.7425 | DC13: 122.4973 | DD13: 3984.625 | DE13: 130.55 | DF13: 520.8129 | DG13: 3989.375 | DH13: 0.9675 | DI13: 3.858 | DJ13: 3987.625 | DK13: 10.8725 | DL13: 43.3663 | DM13: 3988.625 | DN13: 0.08 | DO13: 0.3191 | DP13: 3989.25 | DQ13: 0.65 | DR13: 2.5918 | DS13: 3987.375 | DT13: 3.18 | DU13: 12.6723 | DV13: 3985 | DW13: 0.6 | DX13: 2.3913 | DY13: 3985.5 | DZ13: 0.35 | EA13: 1.3963 | EB13: 3989.5 | EC13: 0.0725 | ED13: 0.2893 | EE13: 3990.375 | EF13: 2.5425 | EG13: 8.423 | EH13: 3312.875 | EI13: 0.31 | EJ13: 0.3719 | EK13: 1199.625 | EL13: -0.02 | EM13: 0 | EN13: 0.75 | EO13: 0.035 | EP13: 0 | EQ13: 0.75
A14: 2.0212 | B14: 16.545 | C14: 122.3565 | D14: 7395.375 | E14: -0.0025 | F14: 0 | G14: 0.75 | H14: -0.07 | I14: -0.0001 | J14: 1.5 | K14: 0 | L14: 0 | M14: 1 | N14: 7.9875 | O14: 36.7725 | P14: 4603.75 | Q14: 3.435 | R14: 6.1899 | S14: 1802 | T14: 10.7875 | U14: 11.4078 | V14: 1057.5 | W14: 3.9 | X14: 3.5914 | Y14: 920.875 | Z14: 1.95 | AA14: 0.9813 | AB14: 503.25 | AC14: 0.0075 | AD14: 0 | AE14: 0.875 | AF14: -0.0125 | AG14: 0 | AH14: 0.25 | AI14: 0 | AJ14: 0 | AK14: 1821.75 | AL14: 0.005 | AM14: 0 | AN14: 1.125 | AO14: -0.7 | AP14: -0.0015 | AQ14: 2.125 | AR14: 52.745 | AS14: 68.1861 | AT14: 1292.75 | AU14: 0.1175 | AV14: 0.3517 | AW14: 2993.125 | AX14: 8.095 | AY14: 14.5629 | AZ14: 1799 | BA14: 0.0575 | BB14: 0.1046 | BC14: 1818.5 | BF14: 1.2925 | BG14: 2.3313 | BH14: 1803.75 | BI14: 0.0625 | BJ14: 0.1595 | BK14: 2552.5 | BL14: 5 | BM14: 17.5431 | BN14: 3508.625 | BO14: 0.0375 | BP14: 0.0682 | BQ14: 1819.375 | BR14: 0.03 | BS14: 0.0546 | BT14: 1820.25 | BU14: 0.1 | BV14: 0.1819 | BW14: 1819.125 | BX14: 2.1 | BY14: 3.8202 | BZ14: 1819.125 | CA14: 0.1875 | CB14: 0.3413 | CC14: 1820.375 | CD14: 538.21 | CE14: 949.4697 | CF14: 1764.125 | CG14: 0.3 | CH14: 0.5452 | CI14: 1817.375 | CJ14: 0.025 | CK14: 0.0455 | CL14: 1820 | CM14: 0.0475 | CN14: 0.0864 | CO14: 1818.75 | CP14: 0 | CQ14: 0 | CR14: 1820.875 | CS14: 0.85 | CT14: 1.5467 | CU14: 1819.625 | CV14: 0.035 | CW14: 0.1152 | CX14: 3290.125 | CY14: 0.45 | CZ14: 1.7942 | DA14: 3987.125 | DB14: 30.4925 | DC14: 121.444 | DD14: 3982.75 | DE14: 128.4 | DF14: 512.316 | DG14: 3990 | DH14: 1.0175 | DI14: 4.0546 | DJ14: 3984.875 | DK14: 10.8525 | DL14: 43.2703 | DM14: 3987.125 | DN14: 0.0625 | DO14: 0.2493 | DP14: 3988.625 | DQ14: 0 | DR14: 0 | DS14: 3986.5 | DT14: 2.825 | DU14: 11.2601 | DV14: 3985.875 | DW14: 0.5 | DX14: 1.9949 | DY14: 3989.75 | DZ14: 1 | EA14: 3.9885 | EB14: 3988.5 | EC14: 0.075 | ED14: 0.2992 | EE14: 3989.125 | EF14: 2.4175 | EG14: 8.0059 | EH14: 3311.625 | EI14: 14.6425 | EJ14: 17.5802 | EK14: 1200.625 | EL14: -0.0175 | EM14: 0 | EN14: 1.25 | EO14: 0.02 | EP14: 0 | EQ14: 1.625
A15: 2.1172 | B15: 13.035 | C15: 96.4036 | D15: 7395.75 | E15: 0.0025 | F15: 0 | G15: 0.5 | H15: -0.0225 | I15: 0 | J15: 1 | K15: -0.015 | L15: 0 | M15: 0.75 | N15: 8.0175 | O15: 36.9136 | P15: 4604.125 | Q15: 2.9425 | R15: 5.3057 | S15: 1803.125 | T15: 8.825 | U15: 9.3291 | V15: 1057.125 | W15: 4 | X15: 3.6835 | Y15: 920.875 | Z15: 0.95 | AA15: 0.4771 | AB15: 502.25 | AC15: -0.0275 | AD15: 0 | AE15: 0.5 | AF15: 0.015 | AG15: 0 | AH15: 1.625 | AI15: 0 | AJ15: 0 | AK15: 1820.75 | AL15: 0.0025 | AM15: 0 | AN15: 0.75 | AO15: 0.4 | AP15: 0.0006 | AQ15: 1.5 | AR15: 47.285 | AS15: 61.1868 | AT15: 1294 | AU15: 0.11 | AV15: 0.3293 | AW15: 2993.25 | AX15: 7.0325 | AY15: 12.6761 | AZ15: 1802.5 | BA15: 0.03 | BB15: 0.0545 | BC15: 1817.625 | BF15: 0.7175 | BG15: 1.2954 | BH15: 1805.375 | BI15: 0.045 | BJ15: 0.1148 | BK15: 2552 | BL15: 5.85 | BM15: 20.5247 | BN15: 3508.5 | BO15: 0.04 | BP15: 0.0728 | BQ15: 1819.75 | BR15: 0.0225 | BS15: 0.041 | BT15: 1820.75 | BU15: 0.75 | BV15: 1.364 | BW15: 1818.625 | BX15: 2 | BY15: 3.6418 | BZ15: 1820.875 | CA15: 0.225 | CB15: 0.4095 | CC15: 1820.125 | CD15: 537.9025 | CE15: 948.6583 | CF15: 1763.625 | CG15: -0.1 | CH15: -0.182 | CI15: 1819.5 | CJ15: -0.0125 | CK15: -0.0227 | CL15: 1818.5 | CM15: 0.21 | CN15: 0.3817 | CO15: 1817.75 | CP15: 0.0375 | CQ15: 0.0683 | CR15: 1822.125 | CS15: -0.1 | CT15: -0.182 | CU15: 1819.625 | CV15: 3.865 | CW15: 12.7482 | CX15: 3298.375 | CY15: 1.25 | CZ15: 4.9878 | DA15: 3990.25 | DB15: 25.5875 | DC15: 102.1005 | DD15: 3990.25 | DE15: 104.25 | DF15: 416.179 | DG15: 3992.125 | DH15: 0.9 | DI15: 3.5923 | DJ15: 3991.5 | DK15: 10.805 | DL15: 43.112 | DM15: 3990 | DN15: 0.005 | DO15: 0.02 | DP15: 3991.625 | DQ15: -0.4 | DR15: -1.5965 | DS15: 3991.125 | DT15: 2.8075 | DU15: 11.2023 | DV15: 3990.125 | DW15: -0.2 | DX15: -0.7982 | DY15: 3990.75 | DZ15: 1.5 | EA15: 5.9904 | EB15: 3993.625 | EC15: 0.07 | ED15: 0.2794 | EE15: 3991.125 | EF15: 0.275 | EG15: 0.9109 | EH15: 3312.375 | EI15: 0.4425 | EJ15: 0.5303 | EK15: 1198.5 | EL15: 0.0275 | EM15: 0.0001 | EN15: 2.625 | EO15: 0.045 | EP15: 0.0001 | EQ15: 1.375
A16: 2.2132 | B16: 15.935 | D16: 7393.5 | E16: -0.0025 | G16: 1.25 | H16: 0.0025 | J16: 1.125 | K16: -0.02 | M16: 1.625 | N16: 7.955 | P16: 4603.75 | Q16: 3.365 | S16: 1804.375 | T16: 11.985 | V16: 1057.5 | W16: 3.55 | Y16: 921.375 | Z16: 1.75 | AB16: 502.5 | AC16: -0.0125 | AE16: 0.25 | AF16: -0.055 | AH16: 1.375 | AI16: 0.0025 | AK16: 1820.25 | AL16: 0.015 | AN16: 1.125 | AO16: -0.85 | AQ16: 0.5 | AR16: 51.97 | AT16: 1291.875 | AU16: 0.1125 | AW16: 2991.5 | AX16: 7.9025 | AZ16: 1801.875 | BA16: -0.0075 | BC16: 1818.625 | BF16: 2.9975 | BH16: 1804.5 | BI16: 0.0325 | BK16: 2548.75 | BL16: 11.3 | BN16: 3509 | BO16: 0.0525 | BQ16: 1820.125 | BR16: 0.055 | BT16: 1821.375 | BU16: -0.1 | BW16: 1820 | BX16: 2.55 | BZ16: 1820.625 | CA16: 0.19 | CC16: 1821 | CD16: 538.66 | CF16: 1765.25 | CG16: -0.55 | CI16: 1821.25 | CJ16: 0.04 | CL16: 1817.125 | CM16: 0.145 | CO16: 1819.125 | CP16: 0.04 | CR16: 1822.5 | CS16: 0.05 | CU16: 1820.25 | CV16: 0.0125 | CX16: 3290.875 | CY16: 0.9 | DA16: 3988.125 | DB16: 31.45 | DD16: 3986.625 | DE16: 118.95 | DG16: 3991.125 | DH16: 0.9625 | DJ16: 3987.875 | DK16: 10.815 | DM16: 3986.875 | DN16: 0.0125 | DP16: 3991.75 | DQ16: -0.55 | DS16: 3988 | DT16: 2.8325 | DV16: 3984.625 | DW16: 1.25 | DY16: 3988.125 | DZ16: 0.8 | EB16: 3990.375 | EC16: 0.0975 | EE16: 3990.5 | EF16: 3.9625 | EH16: 3309.875 | EI16: 0.37 | EK16: 1200.25 | EL16: 0.0125 | EN16: 0.875 | EO16: -0.0025 | EQ16: 1.375
A17: 2.3092 | B17: 15.2275 | D17: 7393.875 | E17: -0.0175 | G17: 0.25 | H17: -0.035 | J17: 1 | K17: -0.025 | M17: 0.75 | N17: 7.88 | P17: 4604.125 | Q17: 3.26 | S17: 1803.5 | T17: 10.99 | V17: 1058.875 | W17: 3.3 | Y17: 922.25 | Z17: 1.8 | AB17: 503.625 | AC17: 0.035 | AE17: 1 | AF17: -0.005 | AH17: 1.625 | AI17: 0.0325 | AK17: 1820.75 | AL17: 0.0225 | AN17: 1.375 | AO17: -0.05 | AQ17: 1 | AR17: 56.3525 | AT17: 1290.625 | AU17: 0.115 | AW17: 2993.375 | AX17: 7.8575 | AZ17: 1800.625 | BA17: 0.05 | BC17: 1817.875 | BF17: 1.96 | BH17: 1806 | BI17: 0.015 | BK17: 2553 | BL17: 8.35 | BN17: 3507.5 | BO17: 0.0225 | BQ17: 1821.5 | BR17: 0.02 | BT17: 1822.5 | BU17: 0.35 | BW17: 1820.125 | BX17: 1.95 | BZ17: 1819.75 | CA17: 0.1775 | CC17: 1818 | CD17: 538.3475 | CF17: 1763.5 | CG17: 0.25 | CI17: 1819.75 | CJ17: -0.0175 | CL17: 1819.75 | CM17: 0.1425 | CO17: 1819.25 | CP17: 0.0025 | CR17: 1820.875 | CS17: 0.6 | CU17: 1819.375 | CV17: 0.0275 | CX17: 3294.875 | CY17: 1.8 | DA17: 3988.375 | DB17: 29.78 | DD17: 3989.125 | DE17: 114.8 | DG17: 3991.125 | DH17: 0.9225 | DJ17: 3988.375 | DK17: 10.865 | DM17: 3990 | DN17: 0.0425 | DP17: 3991 | DQ17: -0.05 | DS17: 3991 | DT17: 2.8475 | DV17: 3990.375 | DW17: 1.15 | DY17: 3987.625 | DZ17: 0.65 | EB17: 3990.875 | EC17: 0.0775 | EE17: 3990.75 | EF17: 0.2625 | EH17: 3311.25 | EI17: 0.44 | EK17: 1199 | EL17: -0.015 | EN17: 1.375 | EO17: -0.0375 | EQ17: 2.125
A18: 2.4052 | B18: 15.41 | C18: 113.9242 | D18: 7392.875 | E18: -0.025 | F18: 0 | G18: 1.25 | H18: -0.0575 | I18: -0.0001 | J18: 1.125 | K18: -0.0025 | L18: 0 | M18: 2.25 | N18: 8.01 | O18: 36.8981 | P18: 4606.5 | Q18: 3.295 | R18: 5.9339 | S18: 1800.875 | T18: 11.9675 | U18: 12.6691 | V18: 1058.625 | W18: 3.1 | X18: 2.8609 | Y18: 922.875 | Z18: 1.35 | AA18: 0.6799 | AB18: 503.625 | AC18: 0 | AD18: 0 | AE18: 0.5 | AF18: 0.025 | AG18: 0.0001 | AH18: 2.125 | AI18: 0.0125 | AJ18: 0.0227 | AK18: 1819.75 | AL18: 0.005 | AM18: 0 | AN18: 0.75 | AO18: -0.45 | AP18: -0.0005 | AQ18: 1.125 | AR18: 53.075 | AS18: 68.5795 | AT18: 1292.125 | AU18: 0.075 | AV18: 0.2243 | AW18: 2990.5 | AX18: 7.9575 | AY18: 14.3155 | AZ18: 1799 | BA18: 0.035 | BB18: 0.0637 | BC18: 1819.875 | BF18: 1.5 | BG18: 2.7056 | BH18: 1803.75 | BI18: 0.0475 | BJ18: 0.1213 | BK18: 2552.75 | BL18: 4.2 | BM18: 14.7389 | BN18: 3509.25 | BO18: 0.05 | BP18: 0.091 | BQ18: 1819.375 | BR18: -0.015 | BS18: -0.0273 | BT18: 1818.75 | BU18: 0.2 | BV18: 0.3638 | BW18: 1819 | BX18: 2.6 | BY18: 4.7346 | BZ18: 1821 | CA18: 0.195 | CB18: 0.3553 | CC18: 1822.125 | CD18: 538.5025 | CE18: 948.7068 | CF18: 1761.75 | CG18: 0.3 | CH18: 0.5466 | CI18: 1821.875 | CJ18: 0.0025 | CK18: 0.0046 | CL18: 1820.125 | CM18: 0.2125 | CN18: 0.3861 | CO18: 1816.875 | CP18: 0.005 | CQ18: 0.0091 | CR18: 1820 | CS18: 1.25 | CT18: 2.2758 | CU18: 1820.625 | CV18: 0.0175 | CW18: 0.0576 | CX18: 3290.125 | CY18: 2 | CZ18: 7.973 | DA18: 3986.5 | DB18: 30.395 | DC18: 121.2267 | DD18: 3988.375 | DE18: 113.3 | DF18: 452.2511 | DG18: 3991.625 | DH18: 0.9475 | DI18: 3.7802 | DJ18: 3989.625 | DK18: 10.8725 | DL18: 43.3677 | DM18: 3988.75 | DN18: 0.0375 | DO18: 0.1496 | DP18: 3989.75 | DQ18: 0.25 | DR18: 0.9971 | DS18: 3988.375 | DT18: 2.9 | DU18: 11.5627 | DV18: 3987.125 | DW18: 0.65 | DX18: 2.5928 | DY18: 3988.875 | DZ18: 0.55 | EA18: 2.194 | EB18: 3989 | EC18: 0.055 | ED18: 0.2195 | EE18: 3991 | EF18: 0.59 | EG18: 1.9523 | EH18: 3309 | EI18: 0.2875 | EJ18: 0.3449 | EK18: 1199.625 | EL18: 0.06 | EM18: 0.0001 | EN18: 1.75 | EO18: 0 | EP18: 0 | EQ18: 1.875
A19: 2.5012 | B19: 15.5625 | C19: 115.0808 | D19: 7394.75 | E19: -0.005 | F19: 0 | G19: 0.75 | H19: -0.02 | I19: 0 | J19: 0.75 | K19: -0.0075 | L19: 0 | M19: 1.25 | N19: 8.02 | O19: 36.9191 | P19: 4603.375 | Q19: 3.995 | R19: 7.2095 | S19: 1804.625 | T19: 8.98 | U19: 9.5098 | V19: 1059 | W19: 3.3 | X19: 3.043 | Y19: 922.125 | Z19: 1.75 | AA19: 0.8796 | AB19: 502.625 | AC19: -0.0025 | AD19: 0 | AE19: 0.75 | AF19: 0.035 | AG19: 0 | AH19: 1 | AI19: 0.0125 | AJ19: 0.0228 | AK19: 1820.125 | AL19: -0.0325 | AM19: 0 | AN19: 1 | AO19: 0.45 | AP19: 0.001 | AQ19: 2.25 | AR19: 57.2075 | AS19: 73.7977 | AT19: 1290 | AU19: 0.0725 | AV19: 0.2169 | AW19: 2991.25 | AX19: 8.2 | AY19: 14.7672 | AZ19: 1800.875 | BA19: -0.0175 | BB19: -0.0318 | BC19: 1817.75 | BF19: 0.395 | BG19: 0.7133 | BH19: 1805.75 | BI19: -0.02 | BJ19: -0.0397 | BK19: 1983.5 | BL19: 4.6 | BM19: 16.1604 | BN19: 3513.125 | BO19: 0.0425 | BP19: 0.0774 | BQ19: 1820.625 | BR19: 0.0325 | BS19: 0.0592 | BT19: 1821.25 | BU19: 0.25 | BV19: 0.4549 | BW19: 1819.625 | BX19: 2.35 | BY19: 4.2752 | BZ19: 1819.25 | CA19: 0.1975 | CB19: 0.3596 | CC19: 1820.875 | CD19: 538.6625 | CE19: 950.7393 | CF19: 1765 | CG19: -0.4 | CH19: -0.7284 | CI19: 1821 | CJ19: 0.01 | CK19: 0.0182 | CL19: 1819.75 | CM19: 0.0925 | CN19: 0.1683 | CO19: 1819.125 | CP19: 0.0475 | CQ19: 0.0865 | CR19: 1821.25 | CS19: 0.55 | CT19: 1.0012 | CU19: 1820.375 | CV19: 0.045 | CW19: 0.1483 | CX19: 3295.625 | CY19: 0.65 | CZ19: 2.5925 | DA19: 3988.5 | DB19: 30.4325 | DC19: 121.3154 | DD19: 3986.375 | DE19: 109.55 | DF19: 437.3647 | DG19: 3992.375 | DH19: 0.975 | DI19: 3.8872 | DJ19: 3986.875 | DK19: 10.555 | DL19: 42.0801 | DM19: 3986.75 | DN19: 0.005 | DO19: 0.02 | DP19: 3991.25 | DQ19: -0.1 | DR19: -0.3987 | DS19: 3987.25 | DT19: 3.165 | DU19: 12.6161 | DV19: 3986.125 | DW19: 0.05 | DX19: 0.1994 | DY19: 3987.875 | DZ19: 0.4 | EA19: 1.5964 | EB19: 3991 | EC19: 0.0225 | ED19: 0.0898 | EE19: 3990.625 | EF19: 0.255 | EG19: 0.8447 | EH19: 3312.625 | EI19: 13.325 | EJ19: 15.9867 | EK19: 1199.75 | EL19: -0.0175 | EM19: 0 | EN19: 0.75 | EO19: -0.0175 | EP19: 0 | EQ19: 0.75
A20: 2.5972 | B20: 13.06 | C20: 96.5461 | D20: 7392.5 | E20: 0.015 | F20: 0 | G20: 0.75 | H20: -0.0275 | I20: 0 | J20: 1.25 | K20: -0.005 | L20: 0 | M20: 2.25 | N20: 7.975 | O20: 36.7299 | P20: 4605.625 | Q20: 2.8325 | R20: 5.1066 | S20: 1802.875 | T20: 7.7225 | U20: 8.1733 | V20: 1058.375 | W20: 2.65 | X20: 2.4443 | Y20: 922.375 | Z20: 1.55 | AA20: 0.7808 | AB20: 503.75 | AC20: 0.0125 | AD20: 0 | AE20: 1.5 | AF20: 0.01 | AG20: 0 | AH20: 0.5 | AI20: 0 | AJ20: 0 | AK20: 1819.75 | AL20: 0.01 | AM20: 0 | AN20: 0.875 | AO20: -0.9 | AP20: -0.0002 | AQ20: 0.25 | AR20: 47.1675 | AS20: 60.9817 | AT20: 1292.875 | AU20: 0.0975 | AV20: 0.2917 | AW20: 2992.25 | AX20: 7.045 | AY20: 12.6889 | AZ20: 1801.125 | BA20: 0.02 | BB20: 0.0364 | BC20: 1819.625 | BF20: 1.1725 | BG20: 2.1174 | BH20: 1805.875 | BI20: -0.04 | BJ20: -0.0072 | BK20: 180.875 | BL20: 8.1 | BM20: 28.432 | BN20: 3510.125 | BO20: 0.04 | BP20: 0.0727 | BQ20: 1818.5 | BR20: 0.0175 | BS20: 0.0319 | BT20: 1821.25 | BU20: -0.2 | BV20: -0.3638 | BW20: 1819 | BX20: 1.2 | BY20: 2.1833 | BZ20: 1819.375 | CA20: 0.1775 | CB20: 0.3231 | CC20: 1820.25 | CD20: 538.4625 | CE20: 950.8575 | CF20: 1765.875 | CG20: 0.1 | CH20: 0.1819 | CI20: 1818.75 | CJ20: -0.0275 | CK20: -0.05 | CL20: 1819.75 | CM20: 0.17 | CN20: 0.3094 | CO20: 1819.75 | CP20: 0.0125 | CQ20: 0.0228 | CR20: 1820.75 | CS20: 0.5 | CT20: 0.9108 | CU20: 1821.625 | CV20: 0.0625 | CW20: 0.2055 | CX20: 3287.25 | CY20: 1.05 | CZ20: 4.1906 | DA20: 3991 | DB20: 25.9475 | DC20: 103.5208 | DD20: 3989.625 | DE20: 115.25 | DF20: 460.078 | DG20: 3992 | DH20: 0.94 | DI20: 3.7534 | DJ20: 3993 | DK20: 10.8525 | DL20: 43.3327 | DM20: 3992.875 | DN20: 0.0325 | DO20: 0.1297 | DP20: 3991.75 | DQ20: 0.45 | DR20: 1.796 | DS20: 3991.125 | DT20: 2.7775 | DU20: 11.0791 | DV20: 3988.875 | DW20: 0.6 | DX20: 2.3954 | DY20: 3992.375 | DZ20: 0.8 | EA20: 3.1931 | EB20: 3991.375 | EC20: 0.0475 | ED20: 0.1897 | EE20: 3993.375 | EF20: 0.4225 | EG20: 1.3994 | EH20: 3312.125 | EI20: 0.405 | EJ20: 0.4861 | EK20: 1200.25 | EL20: -0.025 | EM20: -0.0001 | EN20: 2 | EO20: 0.045 | EP20: 0.0001 | EQ20: 1.125
A21: 2.6932 | B21: 15.455 | C21: 114.3032 | D21: 7395.875 | E21: 0.0075 | F21: 0 | G21: 0.5 | H21: -0.0475 | I21: -0.0001 | J21: 1.875 | K21: -0.0425 | L21: 0 | M21: 0.75 | N21: 7.985 | O21: 36.742 | P21: 4601.375 | Q21: 3.135 | R21: 5.6551 | S21: 1803.875 | T21: 10.7025 | U21: 11.3366 | V21: 1059.25 | W21: 3.95 | X21: 3.6355 | Y21: 920.375 | Z21: 1.15 | AA21: 0.58 | AB21: 504.375 | AC21: -0.0225 | AD21: -0.0001 | AE21: 2.375 | AF21: -0.005 | AG21: 0 | AH21: 0.75 | AI21: 0.0075 | AJ21: 0.0137 | AK21: 1821.125 | AL21: 0.0175 | AM21: 0 | AN21: 1.375 | AO21: 0.45 | AP21: 0.0007 | AQ21: 1.625 | AR21: 56.34 | AS21: 72.7209 | AT21: 1290.75 | AU21: 0.1075 | AV21: 0.3218 | AW21: 2993.625 | AX21: 7.9125 | AY21: 14.2554 | AZ21: 1801.625 | BA21: 0.04 | BB21: 0.0727 | BC21: 1817.375 | BF21: 2.8025 | BG21: 5.0606 | BH21: 1805.75 | BI21: -0.0175 | BJ21: -0.0002 | BK21: 12.25 | BL21: 5.7 | BM21: 20.0127 | BN21: 3511 | BO21: -0.01 | BP21: -0.0182 | BQ21: 1820.5 | BR21: -0.01 | BS21: -0.0182 | BT21: 1822 | BU21: -0.05 | BV21: -0.091 | BW21: 1819.625 | BX21: 2.9 | BY21: 5.2827 | BZ21: 1821.625 | CA21: 0.145 | CB21: 0.2644 | CC21: 1823.75 | CD21: 538.8025 | CE21: 950.3129 | CF21: 1763.75 | CG21: 1.05 | CH21: 1.9113 | CI21: 1820.25 | CJ21: -0.005 | CK21: -0.0091 | CL21: 1818.5 | CM21: 0.1875 | CN21: 0.3413 | CO21: 1820.25 | CP21: 0.0525 | CQ21: 0.0956 | CR21: 1821 | CS21: 0.15 | CT21: 0.2732 | CU21: 1821.5 | CV21: 0.0225 | CW21: 0.074 | CX21: 3290.375 | CY21: 1.6 | CZ21: 6.3828 | DA21: 3989.25 | DB21: 30.8475 | DC21: 122.9774 | DD21: 3986.625 | DE21: 106.9 | DF21: 426.7715 | DG21: 3992.25 | DH21: 0.9625 | DI21: 3.8387 | DJ21: 3988.25 | DK21: 10.5825 | DL21: 42.2229 | DM21: 3989.875 | DN21: 0.08 | DO21: 0.3192 | DP21: 3990.5 | DQ21: 0.85 | DR21: 3.3917 | DS21: 3990.25 | DT21: 2.755 | DU21: 10.9873 | DV21: 3988.125 | DW21: 0.9 | DX21: 3.5912 | DY21: 3990.25 | DZ21: 1.05 | EA21: 4.1906 | EB21: 3991 | EC21: 0.095 | ED21: 0.379 | EE21: 3989.625 | EF21: 0.97 | EG21: 3.2128 | EH21: 3312.125 | EI21: 0.285 | EJ21: 0.3422 | EK21: 1200.75 | EL21: 0 | EM21: 0 | EN21: 2.875 | EO21: 0.01 | EP21: 0 | EQ21: 0.75
A22: 2.7892 | B22: 15.1625 | D22: 7393.625 | E22: -0.0025 | G22: 1.125 | H22: -0.01 | J22: 0.875 | K22: -0.0175 | M22: 1.25 | N22: 7.895 | P22: 4605.625 | Q22: 3.455 | S22: 1803.125 | T22: 10.7875 | V22: 1057.375 | W22: 5.3 | Y22: 922.25 | Z22: 2.25 | AB22: 501.375 | AC22: 0.01 | AE22: 1.125 | AF22: 0.01 | AH22: 1.875 | AI22: 0.0075 | AK22: 1820.75 | AL22: 0.0175 | AN22: 0.25 | AO22: 0.3 | AQ22: 0.25 | AR22: 54.41 | AT22: 1291.125 | AU22: 0.0925 | AW22: 2994.5 | AX22: 7.8975 | AZ22: 1800 | BA22: -0.0025 | BC22: 1818.75 | BF22: 2.965 | BH22: 1805.875 | BI22: 0 | BK22: 3.125 | BL22: 5.05 | BN22: 3510.375 | BO22: 0.045 | BQ22: 1819.375 | BR22: 0.05 | BT22: 1820.125 | BU22: 0 | BW22: 1819.875 | BX22: 1.4 | BZ22: 1819.625 | CA22: 0.1875 | CC22: 1819.5 | CD22: 538.5175 | CF22: 1765.375 | CG22: 0.25 | CI22: 1821.5 | CJ22: 0.045 | CL22: 1820 | CM22: 0.085 | CO22: 1819.625 | CP22: 0.0475 | CR22: 1821 | CS22: 1.15 | CU22: 1820.375 | CV22: 0.0375 | CX22: 3292.875 | CY22: 1.05 | DA22: 3989.75 | DB22: 29.9825 | DD22: 3987.75 | DE22: 117.1 | DG22: 3990.5 | DH22: 0.9825 | DJ22: 3989 | DK22: 10.7525 | DM22: 3989 | DN22: 0.0775 | DP22: 3989.5 | DQ22: 0.7 | DS22: 3990 | DT22: 3.1425 | DV22: 3987.5 | DW22: 0.2 | DY22: 3989.75 | DZ22: 0.7 | EB22: 3989.125 | EC22: 0.0375 | EE22: 3991.25 | EF22: 4.9075 | EH22: 3310.875 | EI22: 0.3125 | EK22: 1199.75 | EL22: 0 | EN22: 0 | EO22: 0.045 | EQ22: 1.75
A23: 2.8852 | B23: 16.3875 | C23: 121.2101 | D23: 7396.5 | E23: -0.005 | F23: 0 | G23: 2.125 | H23: -0.0475 | I23: -0.0001 | J23: 1.375 | K23: -0.0075 | L23: 0 | M23: 1.125 | N23: 7.99 | O23: 36.79 | P23: 4604.5 | Q23: 3.31 | R23: 5.9721 | S23: 1804.25 | T23: 11.895 | U23: 12.5968 | V23: 1059 | W23: 4.45 | X23: 4.0968 | Y23: 920.625 | Z23: 1.35 | AA23: 0.6779 | AB23: 502.125 | AC23: -0.0075 | AD23: 0 | AE23: 0.75 | AF23: -0.0125 | AG23: 0 | AH23: 1.875 | AI23: 0.09 | AJ23: 0.1639 | AK23: 1820.75 | AL23: 0.0025 | AM23: 0 | AN23: 1.375 | AO23: 0.25 | AP23: 0.0001 | AQ23: 0.5 | AR23: 53.895 | AS23: 69.666 | AT23: 1292.625 | AU23: 0.1125 | AV23: 0.3366 | AW23: 2991.875 | AX23: 7.91 | AY23: 14.2291 | AZ23: 1798.875 | BA23: 0.0175 | BB23: 0.0318 | BC23: 1818.375 | BF23: 0.61 | BG23: 1.1023 | BH23: 1807.125 | BI23: -0.0075 | BJ23: 0 | BK23: 4.125 | BL23: 11.7 | BM23: 41.048 | BN23: 3508.375 | BO23: 0.0325 | BP23: 0.0592 | BQ23: 1822.375 | BR23: -0.0075 | BS23: -0.0137 | BT23: 1820.375 | BU23: 0.65 | BV23: 1.1807 | BW23: 1816.5 | BX23: 1.35 | BY23: 2.4565 | BZ23: 1819.625 | CA23: 0.185 | CB23: 0.3368 | CC23: 1820.625 | CD23: 538.5425 | CE23: 949.5851 | CF23: 1763.25 | CG23: 0.25 | CH23: 0.4551 | CI23: 1820.375 | CJ23: 0.02 | CK23: 0.0364 | CL23: 1818.25 | CM23: 0.205 | CN23: 0.3733 | CO23: 1821.125 | CP23: -0.0175 | CQ23: -0.0319 | CR23: 1820.25 | CS23: 0.35 | CT23: 0.6371 | CU23: 1820.25 | CV23: 0.08 | CW23: 0.2634 | CX23: 3293 | CY23: 0.6 | CZ23: 2.3938 | DA23: 3989.625 | DB23: 31.865 | DC23: 127.0139 | DD23: 3986 | DE23: 120.5 | DF23: 480.9758 | DG23: 3991.5 | DH23: 0.9325 | DI23: 3.7179 | DJ23: 3987 | DK23: 10.8325 | DL23: 43.1919 | DM23: 3987.25 | DN23: 0.03 | DO23: 0.1197 | DP23: 3990.125 | DQ23: -0.8 | DR23: -3.1911 | DS23: 3988.875 | DT23: 2.7725 | DU23: 11.0495 | DV23: 3985.375 | DW23: 0.1 | DX23: 0.3992 | DY23: 3992.5 | DZ23: 0 | EA23: 0 | EB23: 3990.125 | EC23: 0.065 | ED23: 0.2595 | EE23: 3992.75 | EF23: 0.2575 | EG23: 0.8527 | EH23: 3311.625 | EI23: 0.2975 | EJ23: 0.3566 | EK23: 1198.625 | EL23: 0.0225 | EM23: 0 | EN23: 1.625 | EO23: -0.0175 | EP23: 0 | EQ23: 1.125
A24: 2.9812 | B24: 15.2925 | C24: 113.088 | D24: 7395 | E24: -0.025 | F24: 0 | G24: 1.875 | H24: 0 | I24: 0 | J24: 0.75 | K24: -0.03 | L24: -0.0001 | M24: 3.25 | N24: 7.9875 | O24: 36.7754 | P24: 4604.125 | Q24: 2.965 | R24: 5.3481 | S24: 1803.75 | T24: 10.275 | U24: 10.862 | V24: 1057.125 | W24: 2 | X24: 1.841 | Y24: 920.5 | Z24: 0.85 | AA24: 0.427 | AB24: 502.375 | AC24: 0.0475 | AD24: 0 | AE24: 0.25 | AF24: -0.01 | AG24: 0 | AH24: 1.5 | AI24: 0.0475 | AJ24: 0.0865 | AK24: 1822 | AL24: -0.0175 | AM24: 0 | AN24: 0.75 | AO24: 0.65 | AP24: 0.0003 | AQ24: 0.5 | AR24: 53.095 | AS24: 68.5324 | AT24: 1290.75 | AU24: 0.105 | AV24: 0.3145 | AW24: 2995 | AX24: 7.8775 | AY24: 14.1844 | AZ24: 1800.625 | BA24: 0 | BB24: 0 | BC24: 1817.875 | BF24: 0.995 | BG24: 1.7996 | BH24: 1808.625 | BI24: -0.025 | BJ24: 0 | BK24: 1.875 | BL24: 6.65 | BM24: 23.339 | BN24: 3509.625 | BO24: 0.06 | BP24: 0.1093 | BQ24: 1821 | BR24: 0.0125 | BS24: 0.0228 | BT24: 1821.625 | BU24: 0.05 | BV24: 0.091 | BW24: 1819.875 | BX24: 1.6 | BY24: 2.9132 | BZ24: 1820.75 | CA24: 0.185 | CB24: 0.3368 | CC24: 1820.625 | CD24: 538.485 | CE24: 949.4837 | CF24: 1763.25 | CG24: 0.55 | CH24: 1.0013 | CI24: 1820.5 | CJ24: 0.025 | CK24: 0.0455 | CL24: 1818.375 | CM24: 0.115 | CN24: 0.2092 | CO24: 1819.125 | CP24: 0.0275 | CQ24: 0.0501 | CR24: 1820.625 | CS24: -0.2 | CT24: -0.364 | CU24: 1820.25 | CV24: 0.005 | CW24: 0.0164 | CX24: 3288.75 | CY24: 0.6 | CZ24: 2.3945 | DA24: 3990.875 | DB24: 29.8575 | DC24: 119.0829 | DD24: 3988.375 | DE24: 107.8 | DF24: 430.4454 | DG24: 3993 | DH24: 0.8925 | DI24: 3.5602 | DJ24: 3989 | DK24: 10.7775 | DL24: 42.9847 | DM24: 3988.375 | DN24: 0.005 | DO24: 0.02 | DP24: 3991.5 | DQ24: 0.15 | DR24: 0.5983 | DS24: 3988.875 | DT24: 2.84 | DU24: 11.3249 | DV24: 3987.625 | DW24: 0.65 | DX24: 2.5922 | DY24: 3988 | DZ24: 1.05 | EA24: 4.1899 | EB24: 3990.375 | EC24: 0.0725 | ED24: 0.2893 | EE24: 3990.375 | EF24: 0.2375 | EG24: 0.7863 | EH24: 3310.875 | EI24: 0.4075 | EJ24: 0.4896 | EK24: 1201.5 | EL24: -0.0525 | EM24: -0.0001 | EN24: 1.125 | EO24: -0.0225 | EP24: 0 | EQ24: 1
A25: 3.0772 | B25: 13.365 | C25: 98.8726 | D25: 7397.875 | E25: 0.0025 | F25: 0 | G25: 0.75 | H25: -0.0075 | I25: 0 | J25: 1 | K25: -0.0025 | L25: 0 | M25: 0.75 | N25: 8.015 | O25: 36.9091 | P25: 4605 | Q25: 3.185 | R25: 5.7453 | S25: 1803.875 | T25: 8.8375 | U25: 9.3412 | V25: 1057 | W25: 3.95 | X25: 3.6424 | Y25: 922.125 | Z25: 1.7 | AA25: 0.8549 | AB25: 502.875 | AC25: 0.0025 | AD25: 0 | AE25: 0.25 | AF25: -0.0175 | AG25: 0 | AH25: 1.75 | AI25: 0.0075 | AJ25: 0.0136 | AK25: 1819.75 | AL25: 0.0225 | AM25: 0.0001 | AN25: 2.25 | AO25: -0.2 | AP25: -0.0001 | AQ25: 0.5 | AR25: 46.4075 | AS25: 59.9991 | AT25: 1292.875 | AU25: 0.12 | AV25: 0.3585 | AW25: 2987.375 | AX25: 7.01 | AY25: 12.6206 | AZ25: 1800.375 | BA25: 0.02 | BB25: 0.0364 | BC25: 1819.125 | BF25: 2.8275 | BG25: 5.1043 | BH25: 1805.25 | BI25: -0.0625 | BJ25: -0.0002 | BK25: 2.75 | BL25: 4.55 | BM25: 15.9751 | BN25: 3511 | BO25: 0.025 | BP25: 0.0455 | BQ25: 1820 | BR25: 0.025 | BS25: 0.0455 | BT25: 1821.625 | BU25: 0.95 | BV25: 1.7283 | BW25: 1819.25 | BX25: 2.15 | BY25: 3.9143 | BZ25: 1820.625 | CA25: 0.215 | CB25: 0.391 | CC25: 1818.625 | CD25: 538.6525 | CE25: 950.587 | CF25: 1764.75 | CG25: 0.25 | CH25: 0.4548 | CI25: 1819.375 | CJ25: 0.02 | CK25: 0.0363 | CL25: 1817.125 | CM25: 0.1375 | CN25: 0.2503 | CO25: 1820.625 | CP25: -0.02 | CQ25: -0.0365 | CR25: 1823.125 | CS25: 0.8 | CT25: 1.4558 | CU25: 1819.75 | CV25: 7.4425 | CW25: 24.4616 | CX25: 3286.75 | CY25: 0.2 | CZ25: 0.7977 | DA25: 3988.75 | DB25: 26.08 | DC25: 104.0266 | DD25: 3988.75 | DE25: 113.15 | DF25: 451.6382 | DG25: 3991.5 | DH25: 0.9325 | DI25: 3.7214 | DJ25: 3990.75 | DK25: 10.79 | DL25: 43.0494 | DM25: 3989.75 | DN25: 0.095 | DO25: 0.3791 | DP25: 3990.125 | DQ25: -0.2 | DR25: -0.798 | DS25: 3990.125 | DT25: 2.8725 | DU25: 11.4541 | DV25: 3987.5 | DW25: 0.9 | DX25: 3.593 | DY25: 3992.25 | DZ25: 1.55 | EA25: 6.1864 | EB25: 3991.25 | EC25: 0.075 | ED25: 0.2994 | EE25: 3992.125 | EF25: 4.735 | EG25: 15.6782 | EH25: 3311.125 | EI25: 0.3525 | EJ25: 0.4235 | EK25: 1201.375 | EL25: 0.0075 | EM25: 0 | EN25: 1.125 | EO25: -0.005 | EP25: 0 | EQ25: 0.5
A26: 3.1732 | B26: 15.64 | C26: 115.6402 | D26: 7393.875 | E26: -0.005 | F26: 0 | G26: 0.25 | H26: -0.0025 | I26: 0 | J26: 1.375 | K26: -0.025 | L26: 0 | M26: 1 | N26: 7.9 | O26: 36.3677 | P26: 4603.5 | Q26: 3.2475 | R26: 5.8524 | S26: 1802.125 | T26: 11.6875 | U26: 12.3581 | V26: 1057.375 | W26: 2.25 | X26: 2.0717 | Y26: 920.75 | Z26: 1.5 | AA26: 0.7541 | AB26: 502.75 | AC26: 0.0075 | AD26: 0 | AE26: 1.125 | AF26: -0.02 | AG26: 0 | AH26: 2.375 | AI26: 0.0025 | AJ26: 0.0046 | AK26: 1820.625 | AL26: 0.0125 | AM26: 0 | AN26: 2.25 | AO26: 0.45 | AP26: 0.0002 | AQ26: 0.5 | AR26: 53.96 | AS26: 69.5612 | AT26: 1289.125 | AU26: 0.1 | AV26: 0.2992 | AW26: 2992 | AX26: 8.41 | AY26: 15.1433 | AZ26: 1800.625 | BA26: 0.045 | BB26: 0.0818 | BC26: 1817.75 | BF26: 1.155 | BG26: 2.0842 | BH26: 1804.5 | BI26: 0.0125 | BJ26: 0 | BK26: 1.875 | BL26: 6.2 | BM26: 21.762 | BN26: 3510 | BO26: 0.0575 | BP26: 0.1048 | BQ26: 1821.875 | BR26: 0.0075 | BS26: 0.0137 | BT26: 1820.875 | BU26: 0.7 | BV26: 1.2723 | BW26: 1817.5 | BX26: 1.3 | BY26: 2.3647 | BZ26: 1819 | CA26: 0.2125 | CB26: 0.3868 | CC26: 1820.25 | CD26: 538.5425 | CE26: 949.7197 | CF26: 1763.5 | CG26: 0.35 | CH26: 0.637 | CI26: 1820 | CJ26: 0.035 | CK26: 0.0636 | CL26: 1818.125 | CM26: 0.1775 | CN26: 0.3229 | CO26: 1818.875 | CP26: -0.005 | CQ26: -0.0091 | CR26: 1820.5 | CS26: -0.1 | CT26: -0.182 | CU26: 1819.625 | CV26: 0.0325 | CW26: 0.1069 | CX26: 3290.5 | CY26: 1 | CZ26: 3.9901 | DA26: 3990.125 | DB26: 30.2225 | DC26: 120.5651 | DD26: 3989.25 | DE26: 102.15 | DF26: 407.7828 | DG26: 3992 | DH26: 0.975 | DI26: 3.8896 | DJ26: 3989.375 | DK26: 10.6425 | DL26: 42.4609 | DM26: 3989.75 | DN26: 0.0275 | DO26: 0.1098 | DP26: 3991.375 | DQ26: -0.45 | DR26: -1.7959 | DS26: 3991 | DT26: 2.5475 | DU26: 10.1613 | DV26: 3988.75 | DW26: -0.1 | DX26: -0.399 | DY26: 3990 | DZ26: 0.6 | EA26: 2.3962 | EB26: 3993.625 | EC26: 0.08 | ED26: 0.3193 | EE26: 3991.75 | EF26: 1.22 | EG26: 4.0406 | EH26: 3312 | EI26: 0.345 | EJ26: 0.4141 | EK26: 1200.25 | EL26: -0.0275 | EM26: 0 | EN26: 1.125 | EO26: -0.055 | EP26: -0.0001 | EQ26: 1.25
A27: 3.2692 | B27: 15.365 | D27: 7394.375 | E27: 0.01 | G27: 1.75 | H27: -0.0025 | J27: 1.375 | K27: -0.0425 | M27: 1 | N27: 7.9925 | P27: 4604 | Q27: 3.1775 | S27: 1803.5 | T27: 11.6175 | V27: 1057.75 | W27: 3.95 | Y27: 922 | Z27: 1.2 | AB27: 502.5 | AC27: -0.0175 | AE27: 1.125 | AF27: -0.0125 | AH27: 1.875 | AI27: 0 | AK27: 1820.75 | AL27: 0.0025 | AN27: 0.75 | AO27: 0.6 | AQ27: 0.5 | AR27: 53.775 | AT27: 1289.375 | AU27: 0.0725 | AW27: 2991.125 | AX27: 7.9225 | AZ27: 1798.125 | BA27: 0.0375 | BC27: 1817.125 | BF27: 0.76 | BH27: 1807.375 | BI27: 0.01 | BK27: 1.5 | BL27: 5.15 | BN27: 3510.625 | BO27: 0.0425 | BQ27: 1820 | BR27: -0.0325 | BT27: 1820.25 | BU27: 0.05 | BW27: 1816.75 | BX27: 2 | BZ27: 1820.25 | CA27: 0.18 | CC27: 1820.625 | CD27: 538.31 | CF27: 1763 | CG27: 0.35 | CI27: 1819.875 | CJ27: 0.0125 | CL27: 1818.75 | CM27: 0.09 | CO27: 1818.625 | CP27: 0.04 | CR27: 1821 | CS27: 0.65 | CU27: 1818.125 | CV27: 0.0475 | CX27: 3293.75 | CY27: 1.25 | DA27: 3990 | DB27: 30.7725 | DD27: 3988.375 | DE27: 123.5 | DG27: 3990.75 | DH27: 0.97 | DJ27: 3990.75 | DK27: 10.7675 | DM27: 3988.75 | DN27: 0.01 | DP27: 3991.875 | DQ27: -0.3 | DS27: 3989.5 | DT27: 2.895 | DV27: 3988.125 | DW27: 0.3 | DY27: 3988.375 | DZ27: 1.1 | EB27: 3988.5 | EC27: 0.0975 | EE27: 3991.875 | EF27: 0.305 | EH27: 3311.375 | EI27: 0.2925 | EK27: 1200 | EL27: -0.0125 | EN27: 1.375 | EO27: -0.0175 | EQ27: 2
A28: 3.3652 | B28: 15.445 | D28: 7393.125 | E28: -0.0075 | G28: 1.375 | H28: -0.005 | J28: 1.125 | K28: -0.0775 | M28: 1 | N28: 8.0225 | P28: 4603 | Q28: 3.27 | S28: 1803.625 | T28: 10.7025 | V28: 1056.25 | W28: 2.05 | Y28: 922.75 | Z28: 1.2 | AB28: 502.75 | AC28: 0.0125 | AE28: 1.375 | AF28: 0.005 | AH28: 1.75 | AI28: 0.0425 | AK28: 1819.875 | AL28: 0.0425 | AN28: 1.375 | AO28: 0 | AQ28: 1.625 | AR28: 54.4625 | AT28: 1291.125 | AU28: 0.085 | AW28: 2993.75 | AX28: 8.1575 | AZ28: 1801.125 | BA28: 0.0075 | BC28: 1818 | BF28: 0.5275 | BH28: 1805.875 | BI28: 0.0225 | BK28: 1.25 | BL28: 7.15 | BN28: 3508.875 | BO28: -0.0175 | BQ28: 1818.875 | BR28: 0.0425 | BT28: 1820.625 | BU28: 0 | BW28: 1817.75 | BX28: 1.5 | BZ28: 1820.75 | CA28: 0.1825 | CC28: 1819.125 | CD28: 538.78 | CF28: 1764 | CG28: 0.4 | CI28: 1819.625 | CJ28: 0.035 | CL28: 1819.875 | CM28: 0.19 | CO28: 1819.75 | CP28: 0.035 | CR28: 1822.25 | CS28: 0.1 | CU28: 1821 | CV28: -0.0025 | CX28: 3295.625 | CY28: 0.95 | DA28: 3990.625 | DB28: 30.63 | DD28: 3986.125 | DE28: 126.9 | DG28: 3989.875 | DH28: 0.9675 | DJ28: 3989.125 | DK28: 10.645 | DM28: 3990 | DN28: 0.0475 | DP28: 3989.375 | DQ28: 0 | DS28: 3988.25 | DT28: 2.97 | DV28: 3987.125 | DW28: 0.95 | DY28: 3989.375 | DZ28: 0.35 | EB28: 3991.375 | EC28: 0.02 | EE28: 3991.5 | EF28: 0.23 | EH28: 3311.75 | EI28: 0.345 | EK28: 1200.375 | EL28: 0.0125 | EN28: 1.25 | EO28: 0.005 | EQ28: 0.75
A29: 3.4612 | B29: 15.1675 | C29: 112.1599 | D29: 7394.75 | E29: -0.0175 | F29: 0 | G29: 1.5 | H29: -0.04 | I29: -0.0001 | J29: 1.375 | K29: -0.03 | L29: -0.0001 | M29: 2 | N29: 7.9925 | O29: 36.7925 | P29: 4603.375 | Q29: 2.9925 | R29: 5.3936 | S29: 1802.375 | T29: 9.7425 | U29: 10.3039 | V29: 1057.625 | W29: 3.9 | X29: 3.5909 | Y29: 920.75 | Z29: 1.4 | AA29: 0.7023 | AB29: 501.625 | AC29: -0.005 | AD29: 0 | AE29: 2.5 | AF29: -0.0025 | AG29: 0 | AH29: 1 | AI29: 0.0125 | AJ29: 0.0228 | AK29: 1820.5 | AL29: 0.0175 | AM29: 0 | AN29: 0.5 | AO29: 0.4 | AP29: 0.0003 | AQ29: 0.75 | AR29: 52.53 | AS29: 67.8885 | AT29: 1292.375 | AU29: 0.045 | AV29: 0.1347 | AW29: 2992.875 | AX29: 7.855 | AY29: 14.1311 | AZ29: 1799 | BA29: 0.035 | BB29: 0.0636 | BC29: 1818.125 | BF29: 2.58 | BG29: 4.6575 | BH29: 1805.25 | BI29: -0.0125 | BJ29: 0 | BK29: 1.5 | BL29: 5.3 | BM29: 18.605 | BN29: 3510.375 | BO29: 0.0625 | BP29: 0.1138 | BQ29: 1820.75 | BR29: 0 | BS29: 0 | BT29: 1821.5 | BU29: 0.9 | BV29: 1.6362 | BW29: 1818 | BX29: 2.25 | BY29: 4.0961 | BZ29: 1820.5 | CA29: 0.17 | CB29: 0.3089 | CC29: 1817.25 | CD29: 538.985 | CE29: 951.9823 | CF29: 1766.25 | CG29: 0.45 | CH29: 0.8184 | CI29: 1818.75 | CJ29: 0.02 | CK29: 0.0363 | CL29: 1817.125 | CM29: 0.16 | CN29: 0.2911 | CO29: 1819.125 | CP29: 0.075 | CQ29: 0.1365 | CR29: 1820.375 | CS29: 0.4 | CT29: 0.7284 | CU29: 1820.875 | CV29: 0.025 | CW29: 0.0823 | CX29: 3292.5 | CY29: 1.45 | CZ29: 5.7842 | DA29: 3989.125 | DB29: 30.2225 | DC29: 120.4858 | DD29: 3986.625 | DE29: 113.8 | DF29: 454.3465 | DG29: 3992.5 | DH29: 0.995 | DI29: 3.9692 | DJ29: 3989.125 | DK29: 10.7375 | DL29: 42.8359 | DM29: 3989.375 | DN29: 0.0725 | DO29: 0.2892 | DP29: 3989.125 | DQ29: -0.65 | DR29: -2.5942 | DS29: 3991.125 | DT29: 2.875 | DU29: 11.4612 | DV29: 3986.5 | DW29: 0.7 | DX29: 2.7941 | DY29: 3991.625 | DZ29: 0.95 | EA29: 3.7911 | EB29: 3990.625 | EC29: 0.06 | ED29: 0.2395 | EE29: 3992 | EF29: 1.2725 | EG29: 4.214 | EH29: 3311.625 | EI29: 0.3925 | EJ29: 0.4717 | EK29: 1201.75 | EL29: 0.005 | EM29: 0 | EN29: 1.5 | EO29: 0.005 | EP29: 0 | EQ29: 2.5
A30: 3.5572 | B30: 13.5425 | C30: 100.1383 | D30: 7394.375 | E30: -0.01 | F30: 0 | G30: 0.75 | H30: -0.0125 | I30: 0 | J30: 1.125 | K30: -0.01 | L30: 0 | M30: 1.375 | N30: 7.9775 | O30: 36.7314 | P30: 4604.375 | Q30: 3.28 | R30: 5.9188 | S30: 1804.5 | T30: 7.2175 | U30: 7.6361 | V30: 1058 | W30: 3.8 | X30: 3.4927 | Y30: 919.125 | Z30: 1.65 | AA30: 0.8306 | AB30: 503.375 | AC30: 0.0025 | AD30: 0 | AE30: 0 | AF30: 0.0175 | AG30: 0 | AH30: 1.625 | AI30: 0 | AJ30: 0 | AK30: 1820.875 | AL30: 0.0075 | AM30: 0 | AN30: 1.875 | AO30: -0.7 | AP30: -0.0014 | AQ30: 2 | AR30: 46.75 | AS30: 60.588 | AT30: 1296 | AU30: 0.085 | AV30: 0.2544 | AW30: 2992.875 | AX30: 7.0875 | AY30: 12.7637 | AZ30: 1800.875 | BA30: 0.0075 | BB30: 0.0136 | BC30: 1819.625 | BF30: 1.47 | BG30: 2.657 | BH30: 1807.5 | BI30: -0.015 | BJ30: 0 | BK30: 1.625 | BL30: 3.7 | BM30: 12.9902 | BN30: 3510.875 | BO30: 0.05 | BP30: 0.0911 | BQ30: 1822.25 | BR30: 0.0325 | BS30: 0.0592 | BT30: 1821.5 | BU30: 0.15 | BV30: 0.2727 | BW30: 1818.125 | BX30: 2.65 | BY30: 4.8263 | BZ30: 1821.25 | CA30: 0.1675 | CB30: 0.3047 | CC30: 1819 | CD30: 538.5025 | CE30: 949.9184 | CF30: 1764 | CG30: 0.1 | CH30: 0.182 | CI30: 1820.25 | CJ30: 0.045 | CK30: 0.0819 | CL30: 1819.5 | CM30: 0.07 | CN30: 0.1274 | CO30: 1820.125 | CP30: 0.0375 | CQ30: 0.0682 | CR30: 1819.875 | CS30: 0.05 | CT30: 0.091 | CU30: 1819.75 | CV30: 0.025 | CW30: 0.0823 | CX30: 3292.125 | CY30: 1.95 | CZ30: 7.781 | DA30: 3990.25 | DB30: 27.79 | DC30: 110.823 | DD30: 3987.875 | DE30: 110.6 | DF30: 441.6258 | DG30: 3993 | DH30: 0.9725 | DI30: 3.8803 | DJ30: 3990 | DK30: 10.6975 | DL30: 42.7031 | DM30: 3991.875 | DN30: -0.01 | DO30: -0.0399 | DP30: 3993.375 | DQ30: -0.45 | DR30: -1.7956 | DS30: 3990.25 | DT30: 2.99 | DU30: 11.9267 | DV30: 3988.875 | DW30: 0.55 | DX30: 2.1956 | DY30: 3992 | DZ30: 0.95 | EA30: 3.793 | EB30: 3992.625 | EC30: 0.115 | ED30: 0.4593 | EE30: 3993.75 | EF30: 0.28 | EG30: 0.9272 | EH30: 3311.5 | EI30: 0.3525 | EJ30: 0.4231 | EK30: 1200.25 | EL30: 0.035 | EM30: 0 | EN30: 1 | EO30: 0 | EP30: 0 | EQ30: 1.25
A31: 3.6532 | B31: 15.2975 | C31: 113.1002 | D31: 7393.375 | E31: -0.0025 | F31: 0 | G31: 2.25 | H31: -0.015 | I31: 0 | J31: 0.75 | K31: 0.0025 | L31: 0 | M31: 1.75 | N31: 7.995 | O31: 36.818 | P31: 4605.125 | Q31: 2.9375 | R31: 5.3026 | S31: 1805.125 | T31: 10.815 | U31: 11.4152 | V31: 1055.5 | W31: 1.75 | X31: 1.6122 | Y31: 921.25 | Z31: 0.85 | AA31: 0.428 | AB31: 503.5 | AC31: -0.0075 | AD31: 0 | AE31: 1.25 | AF31: -0.015 | AG31: 0 | AH31: 1 | AI31: 0.005 | AJ31: 0.0091 | AK31: 1821.25 | AL31: -0.015 | AM31: 0 | AN31: 1.875 | AO31: 0.45 | AP31: 0.0007 | AQ31: 1.625 | AR31: 52.8025 | AS31: 68.2142 | AT31: 1291.875 | AU31: 0.075 | AV31: 0.2244 | AW31: 2992.5 | AX31: 7.84 | AY31: 14.114 | AZ31: 1800.25 | BA31: 0.0425 | BB31: 0.0773 | BC31: 1818.375 | BF31: 2.9525 | BG31: 5.3282 | BH31: 1804.625 | BI31: 0 | BJ31: 0 | BK31: 0.75 | BL31: 12.25 | BM31: 42.9133 | BN31: 3503.125 | BO31: 0.035 | BP31: 0.0637 | BQ31: 1821.375 | BR31: 0.045 | BS31: 0.0819 | BT31: 1819.375 | BU31: 0.35 | BV31: 0.6366 | BW31: 1818.75 | BX31: 2.5 | BY31: 4.5497 | BZ31: 1819.875 | CA31: 0.2075 | CB31: 0.3777 | CC31: 1820.25 | CD31: 538.48 | CE31: 949.6095 | CF31: 1763.5 | CG31: 0.65 | CH31: 1.1834 | CI31: 1820.625 | CJ31: 0.01 | CK31: 0.0182 | CL31: 1819.625 | CM31: 0.2125 | CN31: 0.3869 | CO31: 1820.625 | CP31: -0.0275 | CQ31: -0.0501 | CR31: 1821.625 | CS31: -0.35 | CT31: -0.6369 | CU31: 1819.75 | CV31: 0.0275 | CW31: 0.0905 | CX31: 3290.125 | CY31: 1.9 | CZ31: 7.5836 | DA31: 3991.375 | DB31: 29.8625 | DC31: 119.073 | DD31: 3987.375 | DE31: 110.55 | DF31: 441.3156 | DG31: 3992 | DH31: 0.9425 | DI31: 3.7607 | DJ31: 3990.125 | DK31: 10.9075 | DL31: 43.4964 | DM31: 3987.75 | DN31: 0.0625 | DO31: 0.2494 | DP31: 3990.25 | DQ31: 0 | DR31: 0 | DS31: 3988.625 | DT31: 2.75 | DU31: 10.9677 | DV31: 3988.25 | DW31: 0.95 | DX31: 3.7913 | DY31: 3990.875 | DZ31: 0.35 | EA31: 1.3967 | EB31: 3990.5 | EC31: 0.06 | ED31: 0.2395 | EE31: 3991.75 | EF31: 1.145 | EG31: 3.7927 | EH31: 3312.375 | EI31: 0.3425 | EJ31: 0.4109 | EK31: 1199.75 | EL31: -0.005 | EM31: 0 | EN31: 2 | EO31: 0.015 | EP31: 0 | EQ31: 1.75
A32: 3.7492 | B32: 15.28 | D32: 7394.125 | E32: -0.015 | G32: 1.125 | H32: -0.045 | J32: 1.125 | K32: -0.035 | M32: 1.125 | N32: 7.965 | P32: 4604.75 | Q32: 3.57 | S32: 1802.125 | T32: 10.065 | V32: 1058.125 | W32: 3.3 | Y32: 921.125 | Z32: 1.8 | AB32: 505.5 | AC32: 0.0125 | AE32: 1.375 | AF32: -0.0325 | AH32: 0.75 | AI32: 0.05 | AK32: 1821.625 | AL32: -0.005 | AN32: 1.375 | AO32: 0.4 | AQ32: 2.375 | AR32: 54.3925 | AT32: 1290.875 | AU32: 0.0925 | AW32: 2991.25 | AX32: 7.8875 | AZ32: 1800 | BA32: 0.0425 | BC32: 1818.875 | BF32: 0.4125 | BH32: 1805.875 | BI32: -0.01 | BK32: 1.25 | BL32: 5.35 | BN32: 3509 | BO32: 0.0675 | BQ32: 1821.75 | BR32: 0.035 | BT32: 1819.5 | BU32: 0.55 | BW32: 1817.75 | BX32: 2.35 | BZ32: 1820.625 | CA32: 0.23 | CC32: 1817 | CD32: 538.84 | CF32: 1764.875 | CG32: 1.2 | CI32: 1818.375 | CJ32: 0.055 | CL32: 1817.375 | CM32: 0.1325 | CO32: 1821 | CP32: 0.0475 | CR32: 1821.125 | CS32: -0.25 | CU32: 1820.375 | CV32: 0.0025 | CX32: 3292.25 | CY32: -0.05 | DA32: 3987.375 | DB32: 30.9625 | DD32: 3986.75 | DE32: 126.6 | DG32: 3990.875 | DH32: 0.9625 | DJ32: 3988.25 | DK32: 10.72 | DM32: 3987.125 | DN32: 0.06 | DP32: 3989.5 | DQ32: -0.35 | DS32: 3988.625 | DT32: 2.91 | DV32: 3985.625 | DW32: 0.6 | DY32: 3990.75 | DZ32: 0.7 | EB32: 3988 | EC32: -0.035 | EE32: 3989.25 | EF32: 0.2575 | EH32: 3311.375 | EI32: 0.3125 | EK32: 1199 | EL32: -0.0125 | EN32: 1.75 | EO32: 0.0225 | EQ32: 0.5
